Workbook

Sheet tb
A1: BẢNG TỔNG HỢP THIẾT BỊ
A2: =#REF!
A3: STT | B3: Tên thiết bị | C3: Đơn vị | I3: Tổng số lượng | J3: Đơn giá trước thuế | K3: Thành tiền trước thuế | L3: Thuế suất | M3: Tiền thuế | N3: NSX | O3: Giá vốn vật tư, thiết bị (lấy từ sheet Bao gia) | P3: Giá vốn nhân công (lấy từ sheet Bao gia) | Q3: Đơn giá vật tư đề xuất – GIÁ CHỐT (trước thuế) | R3: Đơn giá nhân công đề xuất – GIÁ CHỐT (trước thuế)
A4: I | B4: Thiết bị
A5: 1 | B5: Bộ nội quy tiêu lệnh chữa cháy - Chất liệu bằng tôn | C5: cái | F5: 5 | I5: =SUM(D5:H5) | J5: 40000 | K5: =J5*I5 | L5: 0.08 | M5: =K5*L5 | N5: vn | O5: ='Bao gia'!J26 | P5: ='Bao gia'!K26 | Q5: ='Danh gia LN'!H84 | R5: ='Danh gia LN'!I84
A6: 2 | B6: Kệ đỡ bình chữa cháy | C6: cái | E6: 5 | F6: 5 | I6: =SUM(D6:H6) | J6: 110000 | K6: =J6*I6 | L6: 0.1 | M6: =K6*L6 | N6: vn | O6: ='Bao gia'!J27 | P6: ='Bao gia'!K27 | Q6: ='Danh gia LN'!H85 | R6: ='Danh gia LN'!I85
A7: 3 | B7: BÌNH BỘT ABC 8KG | C7: cái | E7: 10 | F7: 10 | I7: =SUM(D7:H7) | J7: 550000 | K7: =J7*I7 | L7: 0.08 | M7: =K7*L7 | N7: vn | O7: ='Bao gia'!J28 | P7: ='Bao gia'!K28 | Q7: ='Danh gia LN'!H86 | R7: ='Danh gia LN'!I86
A8: 4 | B8: Sơ đồ chỉ dẫn thoát hiểm 400x600 | C8: cái | D8: 5 | E8: 6 | F8: 6 | G8: 10 | H8: 8 | I8: =SUM(D8:H8) | J8: 150000 | K8: =J8*I8 | L8: 0.08 | M8: =K8*L8 | N8: vn | O8: ='Bao gia'!J32 | P8: ='Bao gia'!K32 | Q8: ='Danh gia LN'!H90 | R8: ='Danh gia LN'!I90
B9: TỔNG TRƯỚC THUẾ | K9: =SUM(K5:K8) | L9: =SUM(L5:L8) | M9: =SUM(M5:M8) | N9: vn
B10: TỔNG SAU THUẾ | K10: =K9+M9

Sheet Bao gia
A1: BẢNG TỔNG HỢP THIẾT BỊ
A2: =#REF!
A3: STT | B3: Tên thiết bị | C3: Đơn vị | D3: Khối lượng | E3: Đơn giá trước thuế | F3: Thành tiền trước thuế | G3: Thuế suất | H3: Tiền thuế | I3: NSX | J3: Giá vốn vật tư, thiết bị (điền giá thực tế) | K3: Giá vốn nhân công (điền giá thực tế) | L3: Đơn giá vật tư đề xuất – GIÁ CHỐT (trước thuế) | M3: Đơn giá nhân công đề xuất – GIÁ CHỐT (trước thuế)
A4: 1 | B4: Trung tâm báo cháy 10 kênh bao gồm Acquy | C4: cái | D4: 2 | E4: 8500000 | F4: =D4*E4 | G4: 0.08 | H4: =F4*G4 | I4: Taiwan | J4: 8600000 | K4: 1500000 | L4: ='Danh gia LN'!H62 | M4: ='Danh gia LN'!I62
A5: 2 | B5: Còi đèn báo cháy kết hợp | C5: cái | D5: 21 | E5: 250000 | F5: =D5*E5 | G5: 0.08 | H5: =F5*G5 | I5: TQ | J5: 252000 | K5: 100000 | L5: ='Danh gia LN'!H63 | M5: ='Danh gia LN'!I63
A6: =A5+1 | B6: Nút ấn khẩn tròn lắp nổi | C6: cái | D6: 21 | E6: 200000 | F6: =D6*E6 | G6: 0.08 | H6: =F6*G6 | I6: TQ | J6: 205000 | K6: 100000 | L6: ='Danh gia LN'!H64 | M6: ='Danh gia LN'!I64
A7: =A6+1 | B7: Đầu báo khói quang 24VDC | C7: cái | D7: 287 | E7: 250000 | F7: =D7*E7 | G7: 0.08 | H7: =F7*G7 | I7: Taiwan | J7: 242000 | K7: 100000 | L7: ='Danh gia LN'!H65 | M7: ='Danh gia LN'!I65
A8: =A7+1 | B8: Đèn báo phòng | C8: cái | D8: 70 | E8: 50000 | F8: =D8*E8 | G8: 0.08 | H8: =F8*G8 | I8: VN | J8: 116000 | K8: 100000 | L8: ='Danh gia LN'!H66 | M8: ='Danh gia LN'!I66
A9: =A8+1 | B9: Cọc tiếp địa mạ đồng D16 L=2,4m | C9: cái | D9: 2 | E9: 280000 | F9: =D9*E9 | G9: 0.1 | H9: =F9*G9 | I9: ấn độ | J9: 252000 | K9: 20000 | L9: ='Danh gia LN'!H67 | M9: ='Danh gia LN'!I67
A10: =A9+1 | B10: Co thép đen hàn DN65 | C10: cái | D10: 56 | E10: 65000 | F10: =D10*E10 | G10: 0.1 | H10: =F10*G10 | I10: TQ | J10: 53000 | K10: 25000 | L10: ='Danh gia LN'!H68 | M10: ='Danh gia LN'!I68
A11: =A10+1 | B11: Co thép đen hàn DN50 | C11: cái | D11: 265 | E11: 50000 | F11: =D11*E11 | G11: 0.1 | H11: =F11*G11 | I11: TQ | J11: 42000 | K11: 25000 | L11: ='Danh gia LN'!H69 | M11: ='Danh gia LN'!I69
A12: =A11+1 | B12: Tê thép đen hàn DN65 | C12: cái | D12: 22 | E12: 165000 | F12: =D12*E12 | G12: 0.1 | H12: =F12*G12 | I12: TQ | J12: 95000 | K12: 25000 | L12: ='Danh gia LN'!H70 | M12: ='Danh gia LN'!I70
A13: =A12+1 | B13: Tê giảm thép đen hàn DN65 | C13: cái | D13: 10 | E13: 1650000 | F13: =D13*E13 | G13: 0.1 | H13: =F13*G13 | I13: TQ | J13: 190000 | K13: 50000 | L13: ='Danh gia LN'!H71 | M13: ='Danh gia LN'!I71
A14: =A13+1 | B14: Tê thép hàn tráng kẽm DN50 | C14: cái | D14: 52 | E14: 150000 | F14: =D14*E14 | G14: 0.1 | H14: =F14*G14 | I14: TQ | J14: 75000 | K14: 25000 | L14: ='Danh gia LN'!H72 | M14: ='Danh gia LN'!I72
A15: =A14+1 | B15: Tê giảm thép hàn DN100/65 | C15: cái | D15: 1 | E15: 180000 | F15: =D15*E15 | G15: 0.1 | H15: =F15*G15 | I15: TQ | J15: 245000 | K15: 50000 | L15: ='Danh gia LN'!H73 | M15: ='Danh gia LN'!I73
A16: =A15+1 | B16: Tê giảm thép hàn DN65/50 | C16: cái | D16: 5 | E16: 150000 | F16: =D16*E16 | G16: 0.1 | H16: =F16*G16 | I16: TQ | J16: 190000 | K16: 50000 | L16: ='Danh gia LN'!H74 | M16: ='Danh gia LN'!I74
A17: =A16+1 | B17: Côn giảm thép hàn DN80/65 | C17: cái | D17: 1 | E17: 80000 | F17: =D17*E17 | G17: 0.1 | H17: =F17*G17 | I17: TQ | J17: 231000 | K17: 50000 | L17: ='Danh gia LN'!H75 | M17: ='Danh gia LN'!I75
... A19: =A18+1 | B19: Roăng su DN80 | C19: cái | D19: 1 | E19: 150000 | F19: =D19*E19 | G19: 0.08 | H19: =F19*G19 | I19: TQ | J19: 17000 | K19: 11538 | L19: ='Danh gia LN'!H77 | M19: ='Danh gia LN'!I77
A20: =A19+1 | B20: ='[1]ĐƠN GIÁ'!B53 | C20: cái | D20: 1 | E20: 350000 | F20: =D20*E20 | G20: 0.1 | H20: =F20*G20 | I20: TQ | J20: 200000 | K20: 100000 | L20: ='Danh gia LN'!H78 | M20: ='Danh gia LN'!I78
A21: =A20+1 | B21: Rơ le kiểm tra mực nước | C21: cái | D21: 4 | F21: =D21*E21 | G21: 0.1 | H21: =F21*G21 | I21: TQ | J21: 2205000 | K21: 150000 | L21: ='Danh gia LN'!H79 | M21: ='Danh gia LN'!I79
A22: =A21+1 | B22: Tủ chữa cháy KT: 400x600x200mm, tole dày 0,8mm, sơn tĩnh điện màu đỏ | C22: cái | D22: 57 | E22: 320000 | F22: =D22*E22 | G22: 0.1 | H22: =F22*G22 | I22: VN | J22: 368000 | K22: 400000 | L22: ='Danh gia LN'!H80 | M22: ='Danh gia LN'!I80
A23: =A22+1 | B23: Cuộn vòi chữa cháy Ø50 - L = 20m + lăng phun | C23: cái | D23: 70 | E23: 480000 | F23: =D23*E23 | G23: 0.08 | H23: =F23*G23 | I23: VN | J23: 514286 | K23: 58022 | L23: ='Danh gia LN'!H81 | M23: ='Danh gia LN'!I81
A24: =A23+1 | B24: Lăng phun DN50 | C24: cái | D24: 70 | E24: 80000 | F24: =D24*E24 | G24: 0.1 | H24: =F24*G24 | I24: VN | J24: 85714 | K24: 9670 | L24: ='Danh gia LN'!H82 | M24: ='Danh gia LN'!I82
A25: =A24+1 | B25: Van góc FUJI DN50 | C25: cái | D25: 70 | E25: 250000 | F25: =D25*E25 | G25: 0.1 | H25: =F25*G25 | I25: VN | J25: 166000 | K25: 100000 | L25: ='Danh gia LN'!H83 | M25: ='Danh gia LN'!I83
A26: =A25+1 | B26: Bộ nội quy tiêu lệnh chữa cháy - Chất liệu bằng tôn | C26: cái | D26: =tb!I5 | E26: 40000 | F26: =D26*E26 | G26: 0.08 | H26: =F26*G26 | I26: VN | J26: 53000 | K26: 50000 | L26: ='Danh gia LN'!H84 | M26: ='Danh gia LN'!I84
A27: =A26+1 | B27: Kệ đỡ bình chữa cháy | C27: cái | D27: =tb!I6 | E27: 110000 | F27: =D27*E27 | G27: 0.1 | H27: =F27*G27 | I27: VN | J27: 137000 | K27: 31538 | L27: ='Danh gia LN'!H85 | M27: ='Danh gia LN'!I85
A28: =A27+1 | B28: BÌNH BỘT ABC 8KG | C28: cái | D28: =tb!I7 | E28: 550000 | F28: =D28*E28 | G28: 0.08 | H28: =F28*G28 | I28: VN | J28: 652000 | K28: 10769 | L28: ='Danh gia LN'!H86 | M28: ='Danh gia LN'!I86
A29: =A28+1 | B29: Đèn exit | C29: cái | D29: 11 | E29: 200000 | F29: =D29*E29 | G29: 0.08 | H29: =F29*G29 | I29: VN | J29: 158000 | K29: 100000 | L29: ='Danh gia LN'!H87 | M29: ='Danh gia LN'!I87
A30: =A29+1 | B30: Đèn chiếu sáng sự cố | C30: cái | D30: 54 | E30: 200000 | F30: =D30*E30 | G30: 0.08 | H30: =F30*G30 | I30: VN | J30: 190000 | K30: 100000 | L30: ='Danh gia LN'!H88 | M30: ='Danh gia LN'!I88
A31: =A30+1 | B31: Đèn báo trạm bơm | C31: cái | F31: =D31*E31 | G31: 0.08 | H31: =F31*G31 | I31: VN | L31: ='Danh gia LN'!H89 | M31: ='Danh gia LN'!I89
A32: =A31+1 | B32: Sơ đồ chỉ dẫn thoát hiểm 400x600 | C32: cái | D32: =tb!I8 | E32: 150000 | F32: =D32*E32 | G32: 0.08 | H32: =F32*G32 | I32: VN | J32: 442000 | K32: 50000 | L32: ='Danh gia LN'!H90 | M32: ='Danh gia LN'!I90
A33: =A32+1 | B33: Họng tiếp nước ngoài nhà 2 cửa- ngàm nhôm | C33: cái | D33: 3 | E33: 950000 | F33: =D33*E33 | G33: 0.1 | H33: =F33*G33 | I33: VN | J33: 1260000 | K33: 500000 | L33: ='Danh gia LN'!H91 | M33: ='Danh gia LN'!I91
B34: TỔNG TRƯỚC THUẾ | F34: =SUM(F4:F33) | H34: =SUM(H4:H33)
B35: TỔNG SAU THUẾ | F35: =F34+H34

Sheet Danh gia LN
A1: ĐÁNH GIÁ GIÁ CHỐT PHẦN PCCC – HỆ THỐNG PCCC CÁC TRƯỜNG TIỂU HỌC, THCS PHƯỜNG ĐỒNG SƠN
A2: Chỉ điều chỉnh đơn giá vật tư/thiết bị có trong báo giá; nhân công theo định mức, các hạng mục khác giữ đơn giá dự toán. QLDA, tư vấn, nhà tạm, dự phòng tính lại theo công thức của bảng tổng dự toán. Giá vốn theo sheet 'Gia von chi tiet'.
R3: VÙNG TÍNH HỆ SỐ TỰ ĐỘNG (không cần sửa)
B4: Lợi nhuận tối thiểu của bên thi công trên giá vốn PCCC | E4: 0.25 | R4: Σ SL quy đổi × giá vốn VT – lắp đặt | S4: =SUMPRODUCT((L62:L91="Lắp đặt")*M62:M91*N(+E62:E91))
B5: Tỷ lệ trích lại chủ đầu tư (trên tổng dự toán gói sau VAT, đã làm tròn) | E5: 0.15 | R5: Σ SL × giá vốn – thiết bị | S5: =SUMPRODUCT((L62:L91="Thiết bị")*D62:D91*N(+E62:E91))
B6: Hệ số: giá đề xuất (vật tư và nhân công) = giá vốn × hệ số (tự tính – nhỏ nhất đạt lợi nhuận ô E4) | E6: =ROUNDUP(MAX(1,$W$27),3) | F6: ← tự tính lại khi sửa giá vốn ở sheet Bao gia hoặc sửa ô E4, E5 (vùng tính phụ ở cột R–W) | R6: VL dự toán hiện tại – lắp đặt | S6: =SUMIF(L62:L91,"Lắp đặt",N62:N91)
B7: Hệ số chi phí trực tiếp → chi phí xây dựng trước thuế: (1 + 7,3% + 2,5%) × (1 + 5,5%) | E7: =(1+7.3%+2.5%)*(1+5.5%) | R7: Giá vốn PCCC (C) | S7: =J92+G111
B8: Tổng mức dùng tính chi phí thẩm tra quyết toán (0,57% × TM) – tự tính | E8: =ROUND(1.05*(H20+H21+H22+H28+500000)/(1-1.05*0.57%),-6) | F8: =IF($E$8=H34,"Khớp tổng làm tròn","⚠ Lệch do làm tròn: tổng = "&TEXT(H34,"#,##0")) | R8: Gxdct1 hiện tại | S8: 1215750394
R9: Xây lắp các trường (giữ nguyên) | S9: 378842471
A10: A. TỔNG DỰ TOÁN GÓI – HIỆN TẠI VÀ SAU KHI CHỐT GIÁ PCCC | R10: Đệm an toàn cho sai số làm tròn (đ) | S10: 300000
B11: Khoản mục chi phí | C11: Ký hiệu | D11: Cách tính | E11: Hiện tại (sau thuế) | F11: Mới – trước thuế | G11: Thuế VAT 8% | H11: MỚI – SAU THUẾ | I11: Chênh (sau thuế) | R11: Σ KL × giá vốn NC (S11) | Σ KL × NC dự toán hiện tại (T11) | S11: =SUMPRODUCT(N(+D62:D91),N(+F62:F91)) | T11: =SUMPRODUCT(N(+D62:D91),N(+Q62:Q91))
B12: Chi phí xây dựng phần PCCC (lắp đặt) | C12: Gxdct1 | D12: Dự toán hiện tại + hệ số × chênh VT, NC | E12: 1313010000 | F12: =1215750394+SUM(O62:O91) | G12: =F12*8% | H12: =ROUND(F12+G12,-3) | I12: =IF(E12="","",H12-E12) | R12: Điểm thử | S12: m = 1 | T12: m = 3 | U12: m₃ (dây cung 1) | V12: m₃ + 0,01
B13: Xây lắp Trường tiểu học Nghĩa Ninh | C13: Gxdct2 | D13: Giữ nguyên | E13: 109257000 | F13: 101163519 | G13: =F13*8% | H13: =ROUND(F13+G13,-3) | I13: =IF(E13="","",H13-E13) | R13: m | S13: 1 | T13: 3 | U13: =T13-T23*(T13-S13)/(T23-S23) | V13: =U13+0.01
B14: Xây lắp Trường tiểu học số 1 Đồng Sơn | C14: Gxdct3 | D14: Giữ nguyên | E14: 42923000 | F14: 39743608 | G14: =F14*8% | H14: =ROUND(F14+G14,-3) | I14: =IF(E14="","",H14-E14) | R14: Gxdct1 | S14: =$S$8+$E$7*(S13*$S$4-$S$6)+$E$7*(S13*$S$11-$T$11) | T14: =$S$8+$E$7*(T13*$S$4-$S$6)+$E$7*(T13*$S$11-$T$11) | U14: =$S$8+$E$7*(U13*$S$4-$S$6)+$E$7*(U13*$S$11-$T$11) | V14: =$S$8+$E$7*(V13*$S$4-$S$6)+$E$7*(V13*$S$11-$T$11)
B15: Xây lắp Trường tiểu học số 2 Đồng Sơn | C15: Gxdct4 | D15: Giữ nguyên | E15: 86464000 | F15: 80058943 | G15: =F15*8% | H15: =ROUND(F15+G15,-3) | I15: =IF(E15="","",H15-E15) | R15: Gxdct | S15: =S14+$S$9 | T15: =T14+$S$9 | U15: =U14+$S$9 | V15: =V14+$S$9
B16: Xây lắp Trường THCS số 1 Đồng Sơn | C16: Gxdct5 | D16: Giữ nguyên | E16: 127297000 | F16: 117867626 | G16: =F16*8% | H16: =ROUND(F16+G16,-3) | I16: =IF(E16="","",H16-E16) | R16: GXD trước thuế | S16: =S15*1.011 | T16: =T15*1.011 | U16: =U15*1.011 | V16: =V15*1.011
B17: Xây lắp Trường THCS Bắc Nghĩa | C17: Gxdct6 | D17: Giữ nguyên | E17: 43209000 | F17: 40008775 | G17: =F17*8% | H17: =ROUND(F17+G17,-3) | I17: =IF(E17="","",H17-E17) | R17: Thiết bị trước thuế | S17: =S13*$S$5 | T17: =T13*$S$5 | U17: =U13*$S$5 | V17: =V13*$S$5
B18: Chi phí xây dựng của công trình | C18: Gxdct | D18: Cộng | F18: =SUM(F12:F17) | G18: =F18*8% | H18: =ROUND(F18+G18,-3) | I18: =IF(E18="","",H18-E18) | R18: QLDA | S18: =(S16+S17)*3.446% | T18: =(T16+T17)*3.446% | U18: =(U16+U17)*3.446% | V18: =(V16+V17)*3.446%
B19: Chi phí nhà tạm để ở và điều hành thi công | C19: Glt | D19: 1,1% × Gxdct | F19: =F18*1.1% | G19: =F19*8% | H19: =ROUND(F19+G19,-3) | I19: =IF(E19="","",H19-E19) | R19: Tư vấn (sau thuế) | S19: =25000000+1.08*((S15+S17)*((3-(S16+S17)/10^9)*0.9+4.7)/100+S15*0.508%) | T19: =25000000+1.08*((T15+T17)*((3-(T16+T17)/10^9)*0.9+4.7)/100+T15*0.508%) | U19: =25000000+1.08*((U15+U17)*((3-(U16+U17)/10^9)*0.9+4.7)/100+U15*0.508%) | V19: =25000000+1.08*((V15+V17)*((3-(V16+V17)/10^9)*0.9+4.7)/100+V15*0.508%)
B20: I. CHI PHÍ XÂY LẮP | C20: GXD | D20: Gxdct + Glt | E20: 1741104000 | F20: =F18+F19 | G20: =F20*8% | H20: =ROUND(F20+G20,-3) | I20: =IF(E20="","",H20-E20) | R20: Tổng gói (ước) | S20: =1.05*(1.08*S16+1.08*S17+S18+S19+500000)/(1-1.05*0.57%) | T20: =1.05*(1.08*T16+1.08*T17+T18+T19+500000)/(1-1.05*0.57%) | U20: =1.05*(1.08*U16+1.08*U17+U18+U19+500000)/(1-1.05*0.57%) | V20: =1.05*(1.08*V16+1.08*V17+V18+V19+500000)/(1-1.05*0.57%)
B21: II. CHI PHÍ THIẾT BỊ | C21: Gtb | D21: Σ thiết bị × giá chốt | E21: 18954000 | F21: =SUMIF(L62:L91,"Thiết bị",K62:K91) | G21: =F21*8% | H21: =F21*1.08 | I21: =IF(E21="","",H21-E21) | R21: Doanh thu PCCC | S21: =S14*1.011+S17 | T21: =T14*1.011+T17 | U21: =U14*1.011+U17 | V21: =V14*1.011+V17
B22: III. CHI PHÍ QUẢN LÝ DỰ ÁN | C22: QL | D22: 3,446% × (GXD + Gtb) | E22: 56159000 | F22: =(F20+F21)*3.446% | H22: =ROUND(F22,-3) | I22: =IF(E22="","",H22-E22) | R22: Trích CĐT | S22: =$E$5*S20 | T22: =$E$5*T20 | U22: =$E$5*U20 | V22: =$E$5*V20
B23: Chi phí đo vẽ hiện trạng | C23: TV1 | D23: Giữ nguyên | E23: 15000000 | F23: =15000000/1.08 | G23: =F23*8% | H23: =15000000 | I23: =IF(E23="","",H23-E23) | R23: f(m) = DT − C − trích − LN tối thiểu | S23: =S21-$S$7-S22-$E$4*$S$7-$S$10 | T23: =T21-$S$7-T22-$E$4*$S$7-$S$10 | U23: =U21-$S$7-U22-$E$4*$S$7-$S$10 | V23: =V21-$S$7-V22-$E$4*$S$7-$S$10
B24: Chi phí lập báo cáo KTKT (nội suy theo quy mô) | C24: TV2 | D24: (Gxdct + Gtb) × tỷ lệ nội suy | F24: =(F18+F21)*(((3-(F20+F21)/10^9)*(6.5-4.7)/(3-1)+4.7)/100) | G24: =F24*8% | H24: =ROUND(F24+G24,-3) | I24: =IF(E24="","",H24-E24)
B25: Chi phí thẩm tra thiết kế BVTC | C25: TV3 | D25: 0,258% × Gxdct | F25: =F18*0.258% | G25: =F25*8% | H25: =ROUND(F25+G25,-3) | I25: =IF(E25="","",H25-E25)
B26: Chi phí thẩm tra dự toán | C26: TV4 | D26: 0,25% × Gxdct | F26: =F18*0.25% | G26: =F26*8% | H26: =ROUND(F26+G26,-3) | I26: =IF(E26="","",H26-E26)
B27: Chi phí thẩm định giá | C27: TV5 | D27: Giữ nguyên | E27: 10000000 | F27: =10000000/1.08 | G27: =F27*8% | H27: =10000000 | I27: =IF(E27="","",H27-E27) | R27: Hệ số tối thiểu (dây cung lần 2) | W27: =U13-U23*(V13-U13)/(V23-U23)
B28: IV. CHI PHÍ TƯ VẤN | C28: GTV | D28: Cộng TV1–TV5 | E28: 137053000 | H28: =ROUND(SUM(H23:H27),-3) | I28: =IF(E28="","",H28-E28)
B29: Chi phí thẩm tra phê duyệt quyết toán | C29: CK1 | D29: 0,57% × TM (ô E8) | F29: =0.57%*$E$8 | H29: =ROUND(F29,-3) | I29: =IF(E29="","",H29-E29)
B30: Phí thẩm định báo cáo KTKT | C30: CK2 | D30: Giữ nguyên | E30: 500000 | F30: 500000 | H30: =ROUND(F30,-3) | I30: =IF(E30="","",H30-E30)
B31: V. CHI PHÍ KHÁC | C31: GK | D31: CK1 + CK2 | E31: 12265000 | H31: =ROUND(H29+H30,-3) | I31: =IF(E31="","",H31-E31)
B32: VI. CHI PHÍ DỰ PHÒNG | C32: GDP | D32: 5% × (GXD + Gtb + QL + GTV + GK) | E32: 98277000 | H32: =ROUND(5%*(H20+H21+H22+H28+H31),-3) | I32: =IF(E32="","",H32-E32)
B33: TỔNG DỰ TOÁN GÓI | C33: VTM | D33: I + … + VI | E33: 2063812000 | H33: =ROUND(H20+H21+H22+H28+H31+H32,-3) | I33: =IF(E33="","",H33-E33)
B34: TỔNG DỰ TOÁN GÓI – LÀM TRÒN (báo chủ đầu tư) | D34: Làm tròn triệu | E34: 2064000000 | H34: =ROUND(H33,-6) | I34: =IF(E34="","",H34-E34)
A36: B. LỢI NHUẬN PHẦN PCCC (trước thuế)
B37: Khoản | E37: Hiện tại | F37: SAU KHI CHỐT GIÁ | G37: Ghi chú
B38: Doanh thu lắp đặt PCCC (Gxdct1) | E38: 1215750394 | F38: =F12
B39: Nhà tạm phần PCCC (1,1% × Gxdct1) | E39: =E38*1.1% | F39: =F38*1.1%
B40: Thiết bị (trước thuế) | E40: 17550000 | F40: =F21
B41: Cộng doanh thu PCCC | E41: =SUM(E38:E40) | F41: =SUM(F38:F40)
...
