Workbook

Sheet Toan goi
A1: ĐÁNH GIÁ TOÀN GÓI PCCC CÁC TRƯỜNG – PHƯỜNG ĐỒNG SƠN
A3: A. TỔNG GIÁ TRỊ XÂY LẮP + THIẾT BỊ
A4: Phần | B4: Tiên lượng | C4: Bộ dự toán | D4: Chênh (DT − tiên lượng) | E4: %
A5: Mầm non (3 trường) | B5: ='Tung truong'!H12 -> 1.493049e+09 | C5: ='Tung truong'!L12 -> 1335394742 | D5: =C5-B5 -> -1.576543e+08 | E5: =D5/B5 -> -0.10559218
A6: Tiểu học – THCS (5 trường) | B6: ='Tung truong'!H13 -> 1.8073752e+09 | C6: ='Tung truong'!L13 -> 1629683388 | D6: =C6-B6 -> -1.776918e+08 | E6: =D6/B6 -> -0.098314839
A7: TOÀN GÓI (8 trường) | B7: ='Tung truong'!H14 -> 3.3004242e+09 | C7: ='Tung truong'!L14 -> 2965078130 | D7: =C7-B7 -> -3.3534611e+08 | E7: =D7/B7 -> -0.10160697
A9: B. TÁCH THEO PHẦN VIỆC (toàn gói)
A10: Phần việc | B10: Tiên lượng | C10: Bộ dự toán | D10: Chênh (DT − tiên lượng) | E10: Ghi chú
A11: Lắp đặt PCCC (gồm vật tư phụ 5%, NC lắp bơm) | B11: =('Tung truong'!C14+'Tung truong'!E14)*'Tung truong'!$U$2 -> 2.4949445e+09 | C11: ='Tung truong'!I14 -> 1963966800 | D11: =C11-B11 -> -5.3097765e+08 | E11: Dự toán thấp hơn: đơn giá ống thép, đầu báo khói, tủ CC, họng, rơ le... thấp hơn tiên lượng
A12: Thiết bị (máy bơm, bình, kệ, nội quy, sơ đồ) | B12: ='Tung truong'!D14*'Tung truong'!$U$2 -> 3.3628932e+08 | C12: ='Tung truong'!K14 -> 138140000 | D12: =C12-B12 -> -1.9814932e+08 | E12: Máy bơm trong sheet tb mầm non 13 / 20,1 tr – thấp hơn cả giá vốn Sao Việt (15,4 / 27,72 tr)
A13: Xây dựng (bể, phòng bơm, cầu thang, đào đắp) | B13: ='Tung truong'!F14*'Tung truong'!$U$2 -> 4.6919046e+08 | C13: ='Tung truong'!J14 -> 862971330 | D13: =C13-B13 -> 3.9378087e+08 | E13: Dự toán cao hơn: tính đủ đào rãnh, đắp cát lót ống, cầu thang sắt, phòng bơm chi tiết
A14: Cộng | B14: =SUM(B11:B13) -> 3.3004242e+09 | C14: =SUM(C11:C13) -> 2965078130 | D14: =C14-B14 -> -3.3534611e+08
A16: C. TỔNG DỰ TOÁN (đã gồm VAT, QLDA, tư vấn, chi phí khác, dự phòng)
A17: Phần | B17: Tiên lượng (THDT 001/002) | C17: Dự toán (sheet TH file Tổng hợp) | D17: Chênh | E17: Ghi chú
A18: Mầm non | B18: 1852068000 | C18: 1699000000 | D18: =C18-B18 -> -153068000 | E18: Tiên lượng không có dự phòng; DT có dự phòng 80,9 tr
A19: Tiểu học – THCS | B19: 2235697000 | C19: 2064000000 | D19: =C19-B19 -> -171697000 | E19: Tiên lượng không có dự phòng; DT có dự phòng 98,3 tr
A20: Cộng | B20: =B18+B19 -> 4087765000 | C20: =C18+C19 -> 3763000000 | D20: =C20-B20 -> -324765000
A22: D. LỢI NHUẬN THEO GIÁ VỐN THỰC (báo giá Sao Việt 01/10/2026 + giá vốn nhập trong sheet ĐƠN GIÁ của 001/002)
A23: Chi phí chung + lán trại thực tế của nhà thầu (% trên giá vốn) – sửa được | B23: 0.084 | E23: Mặc định 7,3% chi phí chung + 1,1% lán trại. Thiết bị không tính khoản này
A24: Phần việc | B24: Dự toán (doanh thu, trước thuế) | C24: Giá vốn (VL + NC) | D24: Lợi nhuận gộp | E24: % LN gộp / DT | F24: LN sau chi phí chung | G24: % LN sau CPC / DT
A25: Lắp đặt PCCC (gồm vật tư phụ, NC lắp bơm) | B25: ='Tung truong'!I14 -> 1963966800 | C25: =SUMIFS('Gia von chi tiet'!$L:$L,'Gia von chi tiet'!$F:$F,"Lắp đặt PCCC")+SUMIFS('Gia von chi tiet'!$L:$L,'Gia von chi tiet'!$F:$F,"Vật tư phụ") -> 1394991022 | D25: =B25-C25 -> 568975778 | E25: =D25/B25 -> 0.28970743 | F25: =D25-C25*$B$23 -> 4.5179653e+08 | G25: =F25/B25 -> 0.23004286
A26: Thiết bị (máy bơm, bình, kệ, nội quy, sơ đồ) | B26: ='Tung truong'!K14 -> 138140000 | C26: =SUMIFS('Gia von chi tiet'!$L:$L,'Gia von chi tiet'!$F:$F,"Thiết bị") -> 186957824 | D26: =B26-C26 -> -48817824 | E26: =D26/B26 -> -0.35339383 | F26: =D26 -> -48817824 | G26: =F26/B26 -> -0.35339383
A27: Xây dựng (DT: file Xây lắp; giá vốn: theo khối lượng tiên lượng) | B27: ='Tung truong'!J14 -> 862971330 | C27: =SUMIFS('Gia von chi tiet'!$L:$L,'Gia von chi tiet'!$F:$F,"Xây dựng") -> 3.5853133e+08 | D27: =B27-C27 -> 5.0444e+08 | E27: =D27/B27 -> 0.58453853 | F27: =D27-C27*$B$23 -> 4.7432336e+08 | G27: =F27/B27 -> 0.54963977
A28: TOÀN GÓI | B28: =SUM(B25:B27) -> 2965078130 | C28: =SUM(C25:C27) -> 1.9404802e+09 | D28: =SUM(D25:D27) -> 1.024598e+09 | E28: =D28/B28 -> 0.34555513 | F28: =SUM(F25:F27) -> 8.7730207e+08 | G28: =F28/B28 -> 0.29587823
A29: Kịch bản thận trọng: phần xây dựng chỉ hòa vốn (chi phí thực bằng dự toán xây lắp) | B29: =B25+B26+B27 -> 2965078130 | C29: =C25+C26+B27 -> 2444920176 | D29: =B29-C29 -> 520157954 | E29: =D29/B29 -> 0.17542808 | F29: =F25+F26 -> 4.0297871e+08 | G29: =F29/B29 -> 0.13590829
A31: Tham chiếu
A32: Chi phí trực tiếp T trong tiên lượng 001/002 | B32: ='Tung truong'!G14 -> 2820887470
A33: Giá vốn (VL + NC) | B33: ='Gia von chi tiet'!L266 -> 1.9404802e+09
A34: → tiên lượng cao hơn giá vốn | B34: =B32/B33-1 -> 0.45370589
A35: Trong giá vốn có phần tạm tính (ô ĐƠN GIÁ còn trống, lấy tiên lượng ÷ 1,3) | B35: ='Gia von chi tiet'!P266 -> 7174566

Sheet De xuat chinh
A1: ĐỀ XUẤT CHỈNH ĐƠN GIÁ DỰ TOÁN – đưa các mục đang thấp hơn giá vốn thực lên ít nhất bằng giá vốn
E2: Hệ số VL → Gxd trước thuế | G2: 1.1711323 | H2: Hệ số trước thuế → TDT (ước) | J2: 1.244
A4: STT | B4: Mục | C4: Phần | D4: ĐVT | E4: KL | F4: Giá DT hiện tại | G4: Giá vốn tạm tính | H4: Giá đề xuất | I4: Tăng/giảm chi phí trực tiếp | J4: Quy ra trước thuế | K4: Ghi chú | L4: Ưu tiên
A5: A. THIẾT BỊ (chi phí thiết bị – sheet tb của file Tổng hợp)
A6: 1 | B6: Máy bơm chữa cháy động cơ diesel Q=45m3/h H=40m | C6: Mầm non | D6: máy | E6: 3 | F6: 20100000 | G6: 27720000 | H6: =MAX(F6,G6) -> 27720000 | I6: =E6*(H6-F6) -> 22860000 | J6: =I6 -> 22860000 | K6: Như trên | L6: 1
A7: 2 | B7: Sơ đồ chỉ dẫn thoát hiểm 400x600 | C7: TH-THCS | D7: cái | E7: 35 | F7: 150000 | G7: 442000 | H7: =MAX(F7,G7) -> 442000 | I7: =E7*(H7-F7) -> 10220000 | J7: =I7 -> 10220000 | L7: 1
A8: 3 | B8: Máy bơm chữa cháy động cơ điện Q=45m3/h H=40m | C8: Mầm non | D8: máy | E8: 3 | F8: 13000000 | G8: 15400000 | H8: =MAX(F8,G8) -> 15400000 | I8: =E8*(H8-F8) -> 7200000 | J8: =I8 -> 7200000 | K8: Sheet tb file Tổng hợp mầm non | L8: 1
A9: 4 | B9: Bình bột ABC 8kg | C9: Mầm non | D9: bình | E9: 28 | F9: 550000 | G9: 652000 | H9: =MAX(F9,G9) -> 652000 | I9: =E9*(H9-F9) -> 2856000 | J9: =I9 -> 2856000 | L9: 2
A10: 5 | B10: Bình bột ABC 8kg | C10: TH-THCS | D10: bình | E10: 20 | F10: 550000 | G10: 652000 | H10: =MAX(F10,G10) -> 652000 | I10: =E10*(H10-F10) -> 2040000 | J10: =I10 -> 2040000 | L10: 2
A11: 6 | B11: Kệ đỡ bình chữa cháy | C11: Mầm non | D11: cái | E11: 14 | F11: 110000 | G11: 137000 | H11: =MAX(F11,G11) -> 137000 | I11: =E11*(H11-F11) -> 378000 | J11: =I11 -> 378000 | L11: 2
A12: B. VẬT TƯ LẮP ĐẶT (chi phí xây dựng – sheet Giá tháng của file PCCC)
A13: 7 | B13: Cáp nguồn trạm bơm 3x10+1x6 | C13: Mầm non | D13: m | E13: 300 | F13: 276910 | G13: 330000 | H13: =MAX(F13,G13) -> 330000 | I13: =E13*(H13-F13) -> 15927000 | J13: =I13*$G$2 -> 18652624 | K13: DT đang có báo giá Cadivi | L13: 1
A14: 8 | B14: Ống thép tráng kẽm DN50 | C14: TH-THCS | D14: m | E14: 570 | F14: 99685 | G14: 120000 | H14: =MAX(F14,G14) -> 120000 | I14: =E14*(H14-F14) -> 11579550 | J14: =I14*$G$2 -> 13561185 | K14: Như trên | L14: 1
A15: 9 | B15: Ống thép tráng kẽm DN65 | C15: TH-THCS | D15: m | E15: 860 | F15: 127270 | G15: 140000 | H15: =MAX(F15,G15) -> 140000 | I15: =E15*(H15-F15) -> 10947800 | J15: =I15*$G$2 -> 12821322 | K15: Giá tháng DT không ghi nguồn | L15: 1
A16: 10 | B16: Đèn báo phòng | C16: TH-THCS | D16: bộ | E16: 70 | F16: 50000 | G16: 116000 | H16: =MAX(F16,G16) -> 116000 | I16: =E16*(H16-F16) -> 4620000 | J16: =I16*$G$2 -> 5410631.2 | L16: 2
A17: 11 | B17: Rơ le kiểm tra mực nước | C17: TH-THCS | D17: bộ | E17: 4 | F17: 1150000 | G17: 2205000 | H17: =MAX(F17,G17) -> 2205000 | I17: =E17*(H17-F17) -> 4220000 | J17: =I17*$G$2 -> 4942178.3 | L17: 2
A18: 12 | B18: Rơ le kiểm tra mực nước | C18: Mầm non | D18: bộ | E18: 3 | F18: 1150000 | G18: 2205000 | H18: =MAX(F18,G18) -> 2205000 | I18: =E18*(H18-F18) -> 3165000 | J18: =I18*$G$2 -> 3706633.7 | L18: 2
A19: 13 | B19: Đèn báo phòng | C19: Mầm non | D19: bộ | E19: 46 | F19: 50000 | G19: 116000 | H19: =MAX(F19,G19) -> 116000 | I19: =E19*(H19-F19) -> 3036000 | J19: =I19*$G$2 -> 3555557.6 | L19: 2
A20: 14 | B20: Ống thép tráng kẽm DN50 | C20: Mầm non | D20: m | E20: 148 | F20: 99685 | G20: 120000 | H20: =MAX(F20,G20) -> 120000 | I20: =E20*(H20-F20) -> 3006620 | J20: =I20*$G$2 -> 3521149.8 | K20: Như trên | L20: 2
A21: 15 | B21: Cuộn vòi D50 20m + lăng phun | C21: TH-THCS | D21: bộ | E21: 70 | F21: 560000 | G21: 600000 | H21: =MAX(F21,G21) -> 600000 | I21: =E21*(H21-F21) -> 2800000 | J21: =I21*$G$2 -> 3279170.4 | K21: DT: vòi 480.000 + lăng 80.000 | L21: 2
A22: 16 | B22: Tủ chữa cháy 400x600x200 | C22: TH-THCS | D22: cái | E22: 57 | F22: 320000 | G22: 368000 | H22: =MAX(F22,G22) -> 368000 | I22: =E22*(H22-F22) -> 2736000 | J22: =I22*$G$2 -> 3204217.9 | L22: 2
A23: 17 | B23: Ống thép tráng kẽm DN65 | C23: Mầm non | D23: m | E23: 212 | F23: 127270 | G23: 140000 | H23: =MAX(F23,G23) -> 140000 | I23: =E23*(H23-F23) -> 2698760 | J23: =I23*$G$2 -> 3160605 | K23: Giá tháng DT không ghi nguồn | L23: 2
A24: 18 | B24: Trung tâm báo cháy 8 kênh | C24: Mầm non | D24: bộ | E24: 2 | F24: 6500000 | G24: 7500000 | H24: =MAX(F24,G24) -> 7500000 | I24: =E24*(H24-F24) -> 2000000 | J24: =I24*$G$2 -> 2342264.6 | L24: 2
A25: 19 | B25: Ống nhựa PVC D25 | C25: Mầm non | D25: m | E25: 116 | F25: 14400 | G25: 25000 | H25: =MAX(F25,G25) -> 25000 | I25: =E25*(H25-F25) -> 1229600 | J25: =I25*$G$2 -> 1440024.3 | L25: 2
A26: 20 | B26: Họng tiếp nước 2 cửa | C26: Mầm non | D26: cái | E26: 3 | F26: 950000 | G26: 1260000 | H26: =MAX(F26,G26) -> 1260000 | I26: =E26*(H26-F26) -> 930000 | J26: =I26*$G$2 -> 1089153 | K26: DT ghi nguồn link thietbi114.vn | L26: 2
A27: 21 | B27: Ống nhựa xoắn HDPE 40/30 | C27: Mầm non | D27: m | E27: 300 | F27: 11900 | G27: 15000 | H27: =MAX(F27,G27) -> 15000 | I27: =E27*(H27-F27) -> 930000 | J27: =I27*$G$2 -> 1089153 | K27: DT theo CBG | L27: 2
A28: 22 | B28: Họng tiếp nước 2 cửa | C28: TH-THCS | D28: cái | E28: 3 | F28: 950000 | G28: 1260000 | H28: =MAX(F28,G28) -> 1260000 | I28: =E28*(H28-F28) -> 930000 | J28: =I28*$G$2 -> 1089153 | K28: DT ghi nguồn link thietbi114.vn | L28: 2
A29: 23 | B29: Tủ chữa cháy 400x600x200 | C29: Mầm non | D29: cái | E29: 17 | F29: 320000 | G29: 368000 | H29: =MAX(F29,G29) -> 368000 | I29: =E29*(H29-F29) -> 816000 | J29: =I29*$G$2 -> 955643.95 | L29: 2
A30: 24 | B30: Đồng hồ áp suất (MN Nghĩa Ninh, Thuận Đức) | C30: Mầm non | D30: bộ | E30: 5 | F30: 163636 | G30: 300000 | H30: =MAX(F30,G30) -> 300000 | I30: =E30*(H30-F30) -> 681820 | J30: =I30*$G$2 -> 798501.42 | K30: MN Đồng Sơn đang để 600.000 | L30: 2
A31: 25 | B31: Cuộn vòi D50 20m + lăng phun | C31: Mầm non | D31: bộ | E31: 17 | F31: 560000 | G31: 600000 | H31: =MAX(F31,G31) -> 600000 | I31: =E31*(H31-F31) -> 680000 | J31: =I31*$G$2 -> 796369.96 | K31: DT: vòi 480.000 + lăng 80.000 | L31: 2
A32: 26 | B32: Trung tâm báo cháy 5 kênh | C32: Mầm non | D32: bộ | E32: 1 | F32: 5500000 | G32: 6150000 | H32: =MAX(F32,G32) -> 6150000 | I32: =E32*(H32-F32) -> 650000 | J32: =I32*$G$2 -> 761235.99 | L32: 2
A33: 27 | B33: Ống nhựa xoắn HDPE 40/30 | C33: TH-THCS | D33: m | E33: 200 | F33: 11900 | G33: 15000 | H33: =MAX(F33,G33) -> 15000 | I33: =E33*(H33-F33) -> 620000 | J33: =I33*$G$2 -> 726102.02 | K33: DT theo CBG | L33: 2
A34: C. SỬA LỖI (làm giảm)
A35: 28 | B35: Co thép đen hàn DN65 (mầm non, đang 650.000) | C35: Mầm non | D35: cái | E35: 40 | F35: 650000 | G35: 53000 | H35: 65000 | I35: =E35*(H35-F35) -> -23400000 | J35: =I35*$G$2 -> -27404496 | K35: Lỗi nhập liệu – đưa về 65.000 như dự toán TH-THCS. Thẩm tra chắc chắn cắt | L35: 1
B37: TỔNG HỢP
B38: A. Thiết bị – tăng | J38: =SUM(J6:J11) -> 45554000
B39: B. Vật tư lắp đặt – tăng (trước thuế) | J39: =SUM(J13:J33) -> 86902876
B40: C. Sửa lỗi – giảm (trước thuế) | J40: =SUM(J35:J35) -> -27404496
B41: Cộng tăng thêm (trước thuế) | J41: =SUM(J38:J40) -> 1.0505238e+08
B42: trong đó chỉ làm các mục ưu tiên 1 | J42: =SUMIF(L5:L35,1,J5:J35) -> 57910635
...

Sheet Tung truong
A1: TOÀN GÓI PCCC PHƯỜNG ĐỒNG SƠN – TỪNG TRƯỜNG: TIÊN LƯỢNG (001, 002) vs BỘ DỰ TOÁN PHẦN MỀM
T2: Hệ số tiên lượng | U2: =(1+7.3%+1.1%+2.5%)*(1+5.5%) -> 1.169995
A3: Gói | B3: Trường | C3: Tiên lượng – PCCC (T) | D3: Tiên lượng – thiết bị (T) | E3: Tiên lượng – vật tư phụ (T) | F3: Tiên lượng – xây dựng (T) | G3: Tiên lượng – cộng T | H3: Tiên lượng – trước thuế | I3: DT – PCCC | J3: DT – Xây lắp | K3: DT – thiết bị | L3: DT – cộng | M3: Chênh (DT − tiên lượng) | N3: % | O3: Giá vốn (VL + NC) | P3: Lợi nhuận gộp (DT − giá vốn) | Q3: % LN gộp / DT | R3: Tiên lượng (T) cao hơn giá vốn
A4: Mầm non | B4: MN Đồng Sơn | C4: 219008000 | D4: 84840000 | E4: 15192400 | F4: 59936000 | G4: =SUM(C4:F4) -> 378976400 | H4: =G4*$U$2 -> 4.4340049e+08 | I4: 226135355 | J4: 172869429 | K4: 41640000 | L4: =SUM(I4:K4) -> 440644784 | M4: =L4-H4 -> -2755709.1 | N4: =M4/H4 -> -0.0062149437 | O4: =SUMIFS('Gia von chi tiet'!$L:$L,'Gia von chi tiet'!$B:$B,B4) -> 2.6476394e+08 | P4: =L4-O4 -> 1.7588084e+08 | Q4: =P4/L4 -> 0.39914427 | R4: =G4/O4-1 -> 0.43137467
A5: Mầm non | B5: MN Nghĩa Ninh | C5: 242563000 | D5: 82078000 | E5: 16232050 | F5: 60428800 | G5: =SUM(C5:F5) -> 401301850 | H5: =G5*$U$2 -> 4.6952116e+08 | I5: 241326764 | J5: 128944866 | K5: 39600000 | L5: =SUM(I5:K5) -> 409871630 | M5: =L5-H5 -> -59649528 | N5: =M5/H5 -> -0.12704332 | O5: =SUMIFS('Gia von chi tiet'!$L:$L,'Gia von chi tiet'!$B:$B,B5) -> 275688529 | P5: =L5-O5 -> 134183101 | Q5: =P5/L5 -> 0.32737836 | R5: =G5/O5-1 -> 0.45563492
A6: Mầm non | B6: MN Thuận Đức | C6: 257102000 | D6: 83020000 | E6: 14781100 | F6: 140934400 | G6: =SUM(C6:F6) -> 495837500 | H6: =G6*$U$2 -> 5.801274e+08 | I6: 267381032 | J6: 178147296 | K6: 39350000 | L6: =SUM(I6:K6) -> 484878328 | M6: =L6-H6 -> -95249068 | N6: =M6/H6 -> -0.16418647 | O6: =SUMIFS('Gia von chi tiet'!$L:$L,'Gia von chi tiet'!$B:$B,B6) -> 363302832 | P6: =L6-O6 -> 121575496 | Q6: =P6/L6 -> 0.25073403 | R6: =G6/O6-1 -> 0.36480494
A7: Tiểu học - THCS | B7: TH số 1 Đồng Sơn | C7: 143038000 | D7: 5310000 | E7: 7417400 | F7: 5192000 | G7: =SUM(C7:F7) -> 160957400 | H7: =G7*$U$2 -> 1.8831935e+08 | I7: 107656356 | J7: 40180788 | K7: 1500000 | L7: =SUM(I7:K7) -> 149337144 | M7: =L7-H7 -> -38982209 | N7: =M7/H7 -> -0.20700055 | O7: =SUMIFS('Gia von chi tiet'!$L:$L,'Gia von chi tiet'!$B:$B,B7) -> 1.1540555e+08 | P7: =L7-O7 -> 33931589 | Q7: =P7/L7 -> 0.22721467 | R7: =G7/O7-1 -> 0.39471103
A8: Tiểu học - THCS | B8: TH số 2 Đồng Sơn | C8: 147256000 | D8: 4248000 | E8: 6171200 | F8: 52488000 | G8: =SUM(C8:F8) -> 210163200 | H8: =G8*$U$2 -> 2.4588989e+08 | I8: 125125607 | J8: 80939591 | K8: 1200000 | L8: =SUM(I8:K8) -> 207265198 | M8: =L8-H8 -> -38624695 | N8: =M8/H8 -> -0.15708126 | O8: =SUMIFS('Gia von chi tiet'!$L:$L,'Gia von chi tiet'!$B:$B,B8) -> 158289369 | P8: =L8-O8 -> 48975829 | Q8: =P8/L8 -> 0.23629548 | R8: =G8/O8-1 -> 0.32771519
A9: Tiểu học - THCS | B9: THCS số 1 Đồng Sơn | C9: 507418000 | D9: 12071000 | E9: 22756450 | F9: 39480000 | G9: =SUM(C9:F9) -> 581725450 | H9: =G9*$U$2 -> 6.8061587e+08 | I9: 505434825 | J9: 119164170 | K9: 6950000 | L9: =SUM(I9:K9) -> 631548995 | M9: =L9-H9 -> -49066873 | N9: =M9/H9 -> -0.072091873 | O9: =SUMIFS('Gia von chi tiet'!$L:$L,'Gia von chi tiet'!$B:$B,B9) -> 3.7525301e+08 | P9: =L9-O9 -> 2.5629598e+08 | Q9: =P9/L9 -> 0.40582122 | R9: =G9/O9-1 -> 0.55022194
A10: Tiểu học - THCS | B10: TH Nghĩa Ninh | C10: 385550400 | D10: 13206000 | E10: 17491320 | F10: 35960000 | G10: =SUM(C10:F10) -> 452207720 | H10: =G10*$U$2 -> 5.2908077e+08 | I10: 391556458 | J10: 102276318 | K10: 7150000 | L10: =SUM(I10:K10) -> 500982776 | M10: =L10-H10 -> -28097995 | N10: =M10/H10 -> -0.053107194 | O10: =SUMIFS('Gia von chi tiet'!$L:$L,'Gia von chi tiet'!$B:$B,B10) -> 289636045 | P10: =L10-O10 -> 211346731 | Q10: =P10/L10 -> 0.42186427 | R10: =G10/O10-1 -> 0.56129642
A11: Tiểu học - THCS | B11: THCS Bắc Nghĩa | C11: 124124000 | D11: 2655000 | E11: 6338950 | F11: 6600000 | G11: =SUM(C11:F11) -> 139717950 | H11: =G11*$U$2 -> 1.634693e+08 | I11: 99350403 | J11: 40448872 | K11: 750000 | L11: =SUM(I11:K11) -> 140549275 | M11: =L11-H11 -> -22920028 | N11: =M11/H11 -> -0.14020998 | O11: =SUMIFS('Gia von chi tiet'!$L:$L,'Gia von chi tiet'!$B:$B,B11) -> 98140896 | P11: =L11-O11 -> 42408379 | Q11: =P11/L11 -> 0.30173318 | R11: =G11/O11-1 -> 0.42364657
A12: Mầm non | B12: Cộng mầm non | C12: =SUM(C4:C6) -> 718673000 | D12: =SUM(D4:D6) -> 249938000 | E12: =SUM(E4:E6) -> 46205550 | F12: =SUM(F4:F6) -> 261299200 | G12: =SUM(G4:G6) -> 1276115750 | H12: =SUM(H4:H6) -> 1.493049e+09 | I12: =SUM(I4:I6) -> 734843151 | J12: =SUM(J4:J6) -> 479961591 | ... M12: =SUM(M4:M6) -> -1.576543e+08 | N12: =M12/H12 -> -0.10559218 | O12: =SUM(O4:O6) -> 9.037553e+08 | P12: =SUM(P4:P6) -> 4.3163944e+08 | Q12: =P12/L12 -> 0.32322985 | R12: =G12/O12-1 -> 0.41201467
A13: Tiểu học - THCS | B13: Cộng tiểu học - thcs | C13: =SUM(C7:C11) -> 1307386400 | D13: =SUM(D7:D11) -> 37490000 | E13: =SUM(E7:E11) -> 60175320 | F13: =SUM(F7:F11) -> 139720000 | G13: =SUM(G7:G11) -> 1544771720 | H13: =SUM(H7:H11) -> 1.8073752e+09 | I13: =SUM(I7:I11) -> 1229123649 | J13: =SUM(J7:J11) -> 383009739 | ... M13: =SUM(M7:M11) -> -1.776918e+08 | N13: =M13/H13 -> -0.098314839 | O13: =SUM(O7:O11) -> 1036724876 | P13: =SUM(P7:P11) -> 592958512 | Q13: =P13/L13 -> 0.3638489 | R13: =G13/O13-1 -> 0.49004982
B14: TOÀN GÓI | C14: =SUM(C4:C11) -> 2026059400 | D14: =SUM(D4:D11) -> 287428000 | E14: =SUM(E4:E11) -> 106380870 | F14: =SUM(F4:F11) -> 401019200 | G14: =SUM(G4:G11) -> 2820887470 | H14: =SUM(H4:H11) -> 3.3004242e+09 | I14: =SUM(I4:I11) -> 1963966800 | J14: =SUM(J4:J11) -> 862971330 | ... M14: =SUM(M4:M11) -> -3.3534611e+08 | N14: =M14/H14 -> -0.10160697 | O14: =SUM(O4:O11) -> 1.9404802e+09 | P14: =SUM(P4:P11) -> 1.024598e+09 | Q14: =P14/L14 -> 0.34555513 | R14: =G14/O14-1 -> 0.45370589

Sheet Gia von chi tiet
A1: GIÁ VỐN TỪNG HẠNG MỤC – 8 TRƯỜNG (khối lượng theo tiên lượng 001/002, đơn giá vốn theo cột G, H sheet ĐƠN GIÁ)
A3: Gói | B3: Trường | C3: Hạng mục | D3: ĐVT | E3: KL | F3: Nhóm | G3: Giá vốn VL | H3: Giá vốn NC | I3: Thành tiền VL | J3: Thành tiền NC | K3: Tiên lượng (thành tiền) | L3: Cộng giá vốn | M3: Tiên lượng − giá vốn | N3: Nguồn giá vốn VL | O3: Nguồn giá vốn NC | P3: Phần tạm tính
A4: Mầm non | B4: MN Thuận Đức | C4: Trung tâm báo cháy 8 kênh bao gồm Acquy | D4: cái | E4: 1 | F4: Lắp đặt PCCC | G4: 7500000 | H4: 1000000 | I4: =E4*G4 -> 7500000 | J4: =E4*H4 -> 1000000 | K4: 12853000 | L4: =I4+J4 -> 8500000 | M4: =K4-L4 -> 4353000 | N4: Nhập trong ĐƠN GIÁ | O4: Nhập trong ĐƠN GIÁ | P4: =IF(LEFT(N4,3)="Tạm",I4,0)+IF(LEFT(O4,3)="Tạm",J4,0) -> 0
A5: Mầm non | B5: MN Thuận Đức | C5: Còi đèn báo cháy kết hợp | D5: cái | E5: 5 | F5: Lắp đặt PCCC | G5: 252000 | H5: 100000 | I5: =E5*G5 -> 1260000 | J5: =E5*H5 -> 500000 | K5: 4125000 | L5: =I5+J5 -> 1760000 | M5: =K5-L5 -> 2365000 | N5: Báo giá Sao Việt | O5: Nhập trong ĐƠN GIÁ | P5: =IF(LEFT(N5,3)="Tạm",I5,0)+IF(LEFT(O5,3)="Tạm",J5,0) -> 0
A6: Mầm non | B6: MN Thuận Đức | C6: Nút ấn khẩn tròn lắp nổi | D6: cái | E6: 5 | F6: Lắp đặt PCCC | G6: 205000 | H6: 100000 | I6: =E6*G6 -> 1025000 | J6: =E6*H6 -> 500000 | K6: 2655000 | L6: =I6+J6 -> 1525000 | M6: =K6-L6 -> 1130000 | N6: Báo giá Sao Việt | O6: Nhập trong ĐƠN GIÁ | P6: =IF(LEFT(N6,3)="Tạm",I6,0)+IF(LEFT(O6,3)="Tạm",J6,0) -> 0
A7: Mầm non | B7: MN Thuận Đức | C7: Đầu báo khói quang 24VDC | D7: cái | E7: 58 | F7: Lắp đặt PCCC | G7: 242000 | H7: 100000 | I7: =E7*G7 -> 14036000 | J7: =E7*H7 -> 5800000 | K7: 32538000 | L7: =I7+J7 -> 19836000 | M7: =K7-L7 -> 12702000 | N7: Báo giá Sao Việt | O7: Nhập trong ĐƠN GIÁ | P7: =IF(LEFT(N7,3)="Tạm",I7,0)+IF(LEFT(O7,3)="Tạm",J7,0) -> 0
A8: Mầm non | B8: MN Thuận Đức | C8: Đèn báo phòng | D8: cái | E8: 14 | F8: Lắp đặt PCCC | G8: 116000 | H8: 100000 | I8: =E8*G8 -> 1624000 | J8: =E8*H8 -> 1400000 | K8: 2534000 | L8: =I8+J8 -> 3024000 | M8: =K8-L8 -> -490000 | N8: Báo giá Sao Việt | O8: Nhập trong ĐƠN GIÁ | P8: =IF(LEFT(N8,3)="Tạm",I8,0)+IF(LEFT(O8,3)="Tạm",J8,0) -> 0
A9: Mầm non | B9: MN Thuận Đức | C9: Đầu báo nhiệt cố định 70 độ C | D9: cái | E9: 3 | F9: Lắp đặt PCCC | G9: 158000 | H9: 100000 | I9: =E9*G9 -> 474000 | J9: =E9*H9 -> 300000 | K9: 783000 | L9: =I9+J9 -> 774000 | M9: =K9-L9 -> 9000 | N9: Báo giá Sao Việt | O9: Nhập trong ĐƠN GIÁ | P9: =IF(LEFT(N9,3)="Tạm",I9,0)+IF(LEFT(O9,3)="Tạm",J9,0) -> 0
A10: Mầm non | B10: MN Thuận Đức | C10: Cáp tín hiệu 2x2x0,5mm2 | D10: m | E10: 850 | F10: Lắp đặt PCCC | G10: 5000 | H10: 5000 | I10: =E10*G10 -> 4250000 | J10: =E10*H10 -> 4250000 | K10: 18700000 | L10: =I10+J10 -> 8500000 | M10: =K10-L10 -> 10200000 | N10: Nhập trong ĐƠN GIÁ | O10: Nhập trong ĐƠN GIÁ | P10: =IF(LEFT(N10,3)="Tạm",I10,0)+IF(LEFT(O10,3)="Tạm",J10,0) -> 0
A11: Mầm non | B11: MN Thuận Đức | C11: Cáp chống cháy chống nhiễu 2x1.5 mm2 | D11: m | E11: 50 | F11: Lắp đặt PCCC | G11: 7500 | H11: 5000 | I11: =E11*G11 -> 375000 | J11: =E11*H11 -> 250000 | K11: 2750000 | L11: =I11+J11 -> 625000 | M11: =K11-L11 -> 2125000 | N11: Nhập trong ĐƠN GIÁ | O11: Nhập trong ĐƠN GIÁ | P11: =IF(LEFT(N11,3)="Tạm",I11,0)+IF(LEFT(O11,3)="Tạm",J11,0) -> 0
A12: Mầm non | B12: MN Thuận Đức | C12: Ống luồn dây PVC D20 | D12: m | E12: 500 | F12: Lắp đặt PCCC | G12: 6000 | H12: 20000 | I12: =E12*G12 -> 3000000 | J12: =E12*H12 -> 10000000 | K12: 21000000 | L12: =I12+J12 -> 13000000 | M12: =K12-L12 -> 8000000 | N12: Nhập trong ĐƠN GIÁ | O12: Nhập trong ĐƠN GIÁ | P12: =IF(LEFT(N12,3)="Tạm",I12,0)+IF(LEFT(O12,3)="Tạm",J12,0) -> 0
A13: Mầm non | B13: MN Thuận Đức | C13: Hệ thống tiếp địa trung tâm báo cháy | D13: ht | E13: 1 | F13: Lắp đặt PCCC | G13: 252000 | H13: 20000 | I13: =E13*G13 -> 252000 | J13: =E13*H13 -> 20000 | K13: 1350000 | L13: =I13+J13 -> 272000 | M13: =K13-L13 -> 1078000 | N13: Báo giá Sao Việt | O13: Nhập trong ĐƠN GIÁ | P13: =IF(LEFT(N13,3)="Tạm",I13,0)+IF(LEFT(O13,3)="Tạm",J13,0) -> 0
A14: Mầm non | B14: MN Thuận Đức | C14: Vật tư phụ | D14: lô | E14: 1 | F14: Vật tư phụ | G14: 1689800 | H14: 1201000 | I14: =E14*G14 -> 1689800 | J14: =E14*H14 -> 1201000 | K14: 4964400 | L14: =I14+J14 -> 2890800 | M14: =K14-L14 -> 2073600 | N14: 5% × giá vốn các dòng 6–15 | O14: 5% × giá vốn các dòng 6–15 | P14: =IF(LEFT(N14,3)="Tạm",I14,0)+IF(LEFT(O14,3)="Tạm",J14,0) -> 0
A15: Mầm non | B15: MN Thuận Đức | C15: Họng tiếp nước ngoài nhà 2 cửa - Ngàm nhôm | D15: cái | E15: 1 | F15: Lắp đặt PCCC | G15: 1260000 | H15: 500000 | I15: =E15*G15 -> 1260000 | J15: =E15*H15 -> 500000 | K15: 3500000 | L15: =I15+J15 -> 1760000 | M15: =K15-L15 -> 1740000 | N15: Báo giá Sao Việt | O15: Nhập trong ĐƠN GIÁ | P15: =IF(LEFT(N15,3)="Tạm",I15,0)+IF(LEFT(O15,3)="Tạm",J15,0) -> 0
... A32: Mầm non | B32: MN Thuận Đức | C32: Tủ điều khiển máy bơm | D32: tủ | E32: 1 | F32: Lắp đặt PCCC | G32: 5500000 | H32: 500000 | I32: =E32*G32 -> 5500000 | J32: =E32*H32 -> 500000 | K32: 10527000 | L32: =I32+J32 -> 6000000 | M32: =K32-L32 -> 4527000 | N32: Nhập trong ĐƠN GIÁ | O32: Nhập trong ĐƠN GIÁ | P32: =IF(LEFT(N32,3)="Tạm",I32,0)+IF(LEFT(O32,3)="Tạm",J32,0) -> 0
A33: Mầm non | B33: MN Thuận Đức | C33: Máy bơm chữa cháy động cơ điện Q: 45m3/h - H: 40m.c.n – giá máy | D33: máy | E33: 1 | F33: Thiết bị | G33: 15400000 | H33: 0 | I33: =E33*G33 -> 15400000 | J33: =E33*H33 -> 0 | K33: 28000000 | L33: =I33+J33 -> 15400000 | M33: =K33-L33 -> 12600000 | N33: Báo giá Sao Việt | P33: =IF(LEFT(N33,3)="Tạm",I33,0)+IF(LEFT(O33,3)="Tạm",J33,0) -> 0
A34: Mầm non | B34: MN Thuận Đức | C34: Máy bơm chữa cháy động cơ điện Q: 45m3/h - H: 40m.c.n – nhân công lắp | D34: máy | E34: 1 | F34: Lắp đặt PCCC | G34: 0 | H34: 3000000 | I34: =E34*G34 -> 0 | J34: =E34*H34 -> 3000000 | K34: 4736000 | L34: =I34+J34 -> 3000000 | M34: =K34-L34 -> 1736000 | O34: Nhập trong ĐƠN GIÁ | P34: =IF(LEFT(N34,3)="Tạm",I34,0)+IF(LEFT(O34,3)="Tạm",J34,0) -> 0
A35: Mầm non | B35: MN Thuận Đức | C35: Máy bơm chữa cháy động cơ nhiên liệu Q: 45m3/h - H: 40m.c.n – giá máy | D35: máy | E35: 1 | F35: Thiết bị | G35: 27720000 | H35: 0 | I35: =E35*G35 -> 27720000 | J35: =E35*H35 -> 0 | K35: 45000000 | L35: =I35+J35 -> 27720000 | M35: =K35-L35 -> 17280000 | N35: Báo giá Sao Việt | P35: =IF(LEFT(N35,3)="Tạm",I35,0)+IF(LEFT(O35,3)="Tạm",J35,0) -> 0
A36: Mầm non | B36: MN Thuận Đức | C36: Máy bơm chữa cháy động cơ nhiên liệu Q: 45m3/h - H: 40m.c.n – nhân công lắp | D36: máy | E36: 1 | F36: Lắp đặt PCCC | G36: 0 | H36: 3000000 | I36: =E36*G36 -> 0 | J36: =E36*H36 -> 3000000 | K36: 4736000 | L36: =I36+J36 -> 3000000 | M36: =K36-L36 -> 1736000 | O36: Nhập trong ĐƠN GIÁ | P36: =IF(LEFT(N36,3)="Tạm",I36,0)+IF(LEFT(O36,3)="Tạm",J36,0) -> 0
A37: Mầm non | B37: MN Thuận Đức | C37: Tủ chữa cháy KT: 400x600x200mm, tole dày 0,8mm, sơn tĩnh điện màu đỏ | D37: tủ | E37: 5 | F37: Lắp đặt PCCC | G37: 368000 | H37: 400000 | I37: =E37*G37 -> 1840000 | J37: =E37*H37 -> 2000000 | K37: 5075000 | L37: =I37+J37 -> 3840000 | M37: =K37-L37 -> 1235000 | N37: Nhập trong ĐƠN GIÁ | O37: Nhập trong ĐƠN GIÁ | P37: =IF(LEFT(N37,3)="Tạm",I37,0)+IF(LEFT(O37,3)="Tạm",J37,0) -> 0
A38: Mầm non | B38: MN Thuận Đức | C38: Cuộn vòi chữa cháy Ø50 - L = 20m + lăng phun | D38: cuộn | E38: 5 | F38: Lắp đặt PCCC | G38: 600000 | H38: 67692 | I38: =E38*G38 -> 3000000 | J38: =E38*H38 -> 338460 | K38: 4160000 | L38: =I38+J38 -> 3338460 | M38: =K38-L38 -> 821540 | N38: Nhập trong ĐƠN GIÁ | O38: Tạm tính | P38: =IF(LEFT(N38,3)="Tạm",I38,0)+IF(LEFT(O38,3)="Tạm",J38,0) -> 338460
A39: Mầm non | B39: MN Thuận Đức | C39: Van góc FUJI DN50 | D39: cái | E39: 5 | F39: Lắp đặt PCCC | G39: 166000 | H39: 100000 | I39: =E39*G39 -> 830000 | J39: =E39*H39 -> 500000 | K39: 2500000 | L39: =I39+J39 -> 1330000 | M39: =K39-L39 -> 1170000 | N39: Báo giá Sao Việt | O39: Nhập trong ĐƠN GIÁ | P39: =IF(LEFT(N39,3)="Tạm",I39,0)+IF(LEFT(O39,3)="Tạm",J39,0) -> 0
A40: Mầm non | B40: MN Thuận Đức | C40: Bộ nội quy tiêu lệnh chữa cháy - Chất liệu bằng tôn | D40: bộ | E40: 5 | F40: Thiết bị | G40: 53000 | H40: 50000 | I40: =E40*G40 -> 265000 | J40: =E40*H40 -> 250000 | K40: 1135000 | L40: =I40+J40 -> 515000 | M40: =K40-L40 -> 620000 | N40: Báo giá Sao Việt | O40: Nhập trong ĐƠN GIÁ | P40: =IF(LEFT(N40,3)="Tạm",I40,0)+IF(LEFT(O40,3)="Tạm",J40,0) -> 0
A41: Mầm non | B41: MN Thuận Đức | C41: Kệ đỡ bình chữa cháy | D41: cái | E41: 5 | F41: Thiết bị | G41: 137000 | H41: 31538 | I41: =E41*G41 -> 685000 | J41: =E41*H41 -> 157690 | K41: 1305000 | L41: =I41+J41 -> 842690 | M41: =K41-L41 -> 462310 | N41: Báo giá Sao Việt | O41: Tạm tính | P41: =IF(LEFT(N41,3)="Tạm",I41,0)+IF(LEFT(O41,3)="Tạm",J41,0) -> 157690
A42: Mầm non | B42: MN Thuận Đức | C42: BÌNH BỘT ABC 8KG | D42: bình | E42: 10 | F42: Thiết bị | G42: 652000 | H42: 10769 | I42: =E42*G42 -> 6520000 | J42: =E42*H42 -> 107690 | K42: 7580000 | L42: =I42+J42 -> 6627690 | M42: =K42-L42 -> 952310 | N42: Báo giá Sao Việt | O42: Tạm tính | P42: =IF(LEFT(N42,3)="Tạm",I42,0)+IF(LEFT(O42,3)="Tạm",J42,0) -> 107690
A43: Mầm non | B43: MN Thuận Đức | C43: Đèn báo trạm bơm | D43: cái | E43: 1 | F43: Lắp đặt PCCC | G43: 285000 | H43: 100000 | I43: =E43*G43 -> 285000 | J43: =E43*H43 -> 100000 | K43: 581000 | L43: =I43+J43 -> 385000 | M43: =K43-L43 -> 196000 | N43: Báo giá Sao Việt | O43: Nhập trong ĐƠN GIÁ | P43: =IF(LEFT(N43,3)="Tạm",I43,0)+IF(LEFT(O43,3)="Tạm",J43,0) -> 0
A44: Mầm non | B44: MN Thuận Đức | C44: Vật tư phụ lắp đặt | D44: lô | E44: 1 | F44: Vật tư phụ | G44: 4825250 | H44: 1460942 | I44: =E44*G44 -> 4825250 | J44: =E44*H44 -> 1460942 | K44: 9816700 | L44: =I44+J44 -> 6286192 | M44: =K44-L44 -> 3530508 | N44: 5% × giá vốn các dòng 17–43 | O44: 5% × giá vốn các dòng 17–43 | P44: =IF(LEFT(N44,3)="Tạm",I44,0)+IF(LEFT(O44,3)="Tạm",J44,0) -> 0
A45: Mầm non | B45: MN Thuận Đức | C45: Cáp cáp nguồn trạm bơm 3x10+1x6mm2 | D45: mét | E45: 100 | F45: Lắp đặt PCCC | G45: 330000 | H45: 10000 | I45: =E45*G45 -> 33000000 | J45: =E45*H45 -> 1000000 | K45: 39500000 | L45: =I45+J45 -> 34000000 | M45: =K45-L45 -> 5500000 | N45: Nhập trong ĐƠN GIÁ | O45: Nhập trong ĐƠN GIÁ | P45: =IF(LEFT(N45,3)="Tạm",I45,0)+IF(LEFT(O45,3)="Tạm",J45,0) -> 0
A46: Mầm non | B46: MN Thuận Đức | C46: Ống nhựa xoắn HDPE 40/30 | D46: mét | E46: 100 | F46: Lắp đặt PCCC | G46: 15000 | H46: 10000 | I46: =E46*G46 -> 1500000 | J46: =E46*H46 -> 1000000 | K46: 5000000 | L46: =I46+J46 -> 2500000 | M46: =K46-L46 -> 2500000 | N46: Nhập trong ĐƠN GIÁ | O46: Nhập trong ĐƠN GIÁ | P46: =IF(LEFT(N46,3)="Tạm",I46,0)+IF(LEFT(O46,3)="Tạm",J46,0) -> 0
A47: Mầm non | B47: MN Thuận Đức | C47: Xây mới bể nước 10m3 | D47: m2 | E47: 1 | F47: Xây dựng | G47: 4500000 | H47: 40000000 | I47: =E47*G47 -> 4500000 | J47: =E47*H47 -> 40000000 | K47: 49500000 | L47: =I47+J47 -> 44500000 | M47: =K47-L47 -> 5000000 | N47: Nhập trong ĐƠN GIÁ | O47: Nhập trong ĐƠN GIÁ | P47: =IF(LEFT(N47,3)="Tạm",I47,0)+IF(LEFT(O47,3)="Tạm",J47,0) -> 0
A48: Mầm non | B48: MN Thuận Đức | C48: Xây lắp mới phòng bơm (KT: D*R*C=2,5*3*2,2) | D48: m2 | E48: 1 | F48: Xây dựng | G48: 1000000 | H48: 10000000 | I48: =E48*G48 -> 1000000 | J48: =E48*H48 -> 10000000 | K48: 8500000 | L48: =I48+J48 -> 11000000 | M48: =K48-L48 -> -2500000 | N48: Nhập trong ĐƠN GIÁ | O48: Nhập trong ĐƠN GIÁ | P48: =IF(LEFT(N48,3)="Tạm",I48,0)+IF(LEFT(O48,3)="Tạm",J48,0) -> 0
... A79: Mầm non | B79: MN Nghĩa Ninh | C79: Tủ điều khiển máy bơm | D79: tủ | E79: 1 | F79: Lắp đặt PCCC | G79: 5500000 | H79: 500000 | I79: =E79*G79 -> 5500000 | J79: =E79*H79 -> 500000 | K79: 10527000 | L79: =I79+J79 -> 6000000 | M79: =K79-L79 -> 4527000 | N79: Nhập trong ĐƠN GIÁ | O79: Nhập trong ĐƠN GIÁ | P79: =IF(LEFT(N79,3)="Tạm",I79,0)+IF(LEFT(O79,3)="Tạm",J79,0) -> 0
A80: Mầm non | B80: MN Nghĩa Ninh | C80: Máy bơm chữa cháy động cơ điện Q: 45m3/h - H: 40m.c.n – giá máy | D80: máy | E80: 1 | F80: Thiết bị | G80: 15400000 | H80: 0 | I80: =E80*G80 -> 15400000 | J80: =E80*H80 -> 0 | K80: 28000000 | L80: =I80+J80 -> 15400000 | M80: =K80-L80 -> 12600000 | N80: Báo giá Sao Việt | P80: =IF(LEFT(N80,3)="Tạm",I80,0)+IF(LEFT(O80,3)="Tạm",J80,0) -> 0
A81: Mầm non | B81: MN Nghĩa Ninh | C81: Máy bơm chữa cháy động cơ điện Q: 45m3/h - H: 40m.c.n – nhân công lắp | D81: máy | E81: 1 | F81: Lắp đặt PCCC | G81: 0 | H81: 3000000 | I81: =E81*G81 -> 0 | J81: =E81*H81 -> 3000000 | K81: 4736000 | L81: =I81+J81 -> 3000000 | M81: =K81-L81 -> 1736000 | O81: Nhập trong ĐƠN GIÁ | P81: =IF(LEFT(N81,3)="Tạm",I81,0)+IF(LEFT(O81,3)="Tạm",J81,0) -> 0
A82: Mầm non | B82: MN Nghĩa Ninh | C82: Máy bơm chữa cháy động cơ nhiên liệu Q: 45m3/h - H: 40m.c.n – giá máy | D82: máy | E82: 1 | F82: Thiết bị | G82: 27720000 | H82: 0 | I82: =E82*G82 -> 27720000 | J82: =E82*H82 -> 0 | K82: 45000000 | L82: =I82+J82 -> 27720000 | M82: =K82-L82 -> 17280000 | N82: Báo giá Sao Việt | P82: =IF(LEFT(N82,3)="Tạm",I82,0)+IF(LEFT(O82,3)="Tạm",J82,0) -> 0
A83: Mầm non | B83: MN Nghĩa Ninh | C83: Máy bơm chữa cháy động cơ nhiên liệu Q: 45m3/h - H: 40m.c.n – nhân công lắp | D83: máy | E83: 1 | F83: Lắp đặt PCCC | G83: 0 | H83: 3000000 | I83: =E83*G83 -> 0 | J83: =E83*H83 -> 3000000 | K83: 4736000 | L83: =I83+J83 -> 3000000 | M83: =K83-L83 -> 1736000 | O83: Nhập trong ĐƠN GIÁ | P83: =IF(LEFT(N83,3)="Tạm",I83,0)+IF(LEFT(O83,3)="Tạm",J83,0) -> 0
A84: Mầm non | B84: MN Nghĩa Ninh | C84: Tủ chữa cháy KT: 400x600x200mm, tole dày 0,8mm, sơn tĩnh điện màu đỏ | D84: tủ | E84: 6 | F84: Lắp đặt PCCC | G84: 368000 | H84: 400000 | I84: =E84*G84 -> 2208000 | J84: =E84*H84 -> 2400000 | K84: 6090000 | L84: =I84+J84 -> 4608000 | M84: =K84-L84 -> 1482000 | N84: Nhập trong ĐƠN GIÁ | O84: Nhập trong ĐƠN GIÁ | P84: =IF(LEFT(N84,3)="Tạm",I84,0)+IF(LEFT(O84,3)="Tạm",J84,0) -> 0
A85: Mầm non | B85: MN Nghĩa Ninh | C85: Cuộn vòi chữa cháy Ø50 - L = 20m + lăng phun | D85: cuộn | E85: 6 | F85: Lắp đặt PCCC | G85: 600000 | H85: 67692 | I85: =E85*G85 -> 3600000 | J85: =E85*H85 -> 406152 | K85: 4992000 | L85: =I85+J85 -> 4006152 | M85: =K85-L85 -> 985848 | N85: Nhập trong ĐƠN GIÁ | O85: Tạm tính | P85: =IF(LEFT(N85,3)="Tạm",I85,0)+IF(LEFT(O85,3)="Tạm",J85,0) -> 406152
A86: Mầm non | B86: MN Nghĩa Ninh | C86: Van góc FUJI DN50 | D86: cái | E86: 6 | F86: Lắp đặt PCCC | G86: 166000 | H86: 100000 | I86: =E86*G86 -> 996000 | J86: =E86*H86 -> 600000 | K86: 3000000 | L86: =I86+J86 -> 1596000 | M86: =K86-L86 -> 1404000 | N86: Báo giá Sao Việt | O86: Nhập trong ĐƠN GIÁ | P86: =IF(LEFT(N86,3)="Tạm",I86,0)+IF(LEFT(O86,3)="Tạm",J86,0) -> 0
A87: Mầm non | B87: MN Nghĩa Ninh | C87: Bộ nội quy tiêu lệnh chữa cháy - Chất liệu bằng tôn | D87: bộ | E87: 4 | F87: Thiết bị | G87: 53000 | H87: 50000 | I87: =E87*G87 -> 212000 | J87: =E87*H87 -> 200000 | K87: 908000 | L87: =I87+J87 -> 412000 | M87: =K87-L87 -> 496000 | N87: Báo giá Sao Việt | O87: Nhập trong ĐƠN GIÁ | P87: =IF(LEFT(N87,3)="Tạm",I87,0)+IF(LEFT(O87,3)="Tạm",J87,0) -> 0
...

Sheet MN chi tiet
A1: MẦM NON: CHI TIẾT TỪNG HẠNG MỤC (thành tiền, chi phí trực tiếp, trước thuế)
A3: Trường | B3: Hạng mục | C3: KL 001 | D3: KL DT | E3: VL 001 | F3: VL DT | G3: NC 001 | H3: NC+M DT | I3: Cộng 001 | J3: Cộng DT | K3: Chênh (DT − 001) | L3: Ghi chú
A4: MN Đồng Sơn | B4: Trung tâm báo cháy 5 kênh bao gồm Acquy | C4: 1 | D4: 1 | E4: 9471000 | F4: 5781825 | G4: 1250000 | H4: 832812 | I4: =E4+G4 -> 10721000 | J4: =F4+H4 -> 6614637 | K4: =J4-I4 -> -4106363
A5: MN Đồng Sơn | B5: Còi đèn báo cháy kết hợp | C5: 6 | D5: 6 | E5: 4464000 | F5: 1545300 | G5: 486000 | H5: 467329 | I5: =E5+G5 -> 4950000 | J5: =F5+H5 -> 2012629 | K5: =J5-I5 -> -2937371
A6: MN Đồng Sơn | B6: Nút ấn khẩn tròn lắp nổi | C6: 6 | D6: 6 | E6: 2700000 | F6: 1239300 | G6: 486000 | H6: 1158901 | I6: =E6+G6 -> 3186000 | J6: =F6+H6 -> 2398201 | K6: =J6-I6 -> -787799
A7: MN Đồng Sơn | B7: Đầu báo khói quang 24VDC | C7: 48 | D7: 48 | E7: 23040000 | F7: 21029448 | G7: 3888000 | H7: 2741141 | I7: =E7+G7 -> 26928000 | J7: =F7+H7 -> 23770589 | K7: =J7-I7 -> -3157411
A8: MN Đồng Sơn | B8: Đèn báo phòng | C8: 12 | D8: 12 | E8: 1200000 | F8: 642600 | G8: 972000 | H8: 934658 | I8: =E8+G8 -> 2172000 | J8: =F8+H8 -> 1577258 | K8: =J8-I8 -> -594742
A9: MN Đồng Sơn | B9: Cáp tín hiệu 2x2x0,5mm2 | C9: 600 | D9: 600 | E9: 7200000 | F9: 11778000 | G9: 6000000 | H9: 4352400 | I9: =E9+G9 -> 13200000 | J9: =F9+H9 -> 16130400 | K9: =J9-I9 -> 2930400
A10: MN Đồng Sơn | B10: Cáp chống cháy chống nhiễu 2x1.5 mm2 | C10: 30 | D10: 30 | E10: 1350000 | F10: 1580100 | G10: 300000 | H10: 264930 | I10: =E10+G10 -> 1650000 | J10: =F10+H10 -> 1845030 | K10: =J10-I10 -> 195030
A11: MN Đồng Sơn | B11: Ống luồn dây PVC D20 | C11: 200 | D11: 200 | E11: 3000000 | F11: 1789000 | G11: 5400000 | H11: 9492800 | I11: =E11+G11 -> 8400000 | J11: =F11+H11 -> 11281800 | K11: =J11-I11 -> 2881800
A12: MN Đồng Sơn | B12: Hệ thống tiếp địa trung tâm báo cháy | C12: 1 | D12: 1 | E12: 850000 | F12: 282800 | G12: 500000 | H12: 100928 | I12: =E12+G12 -> 1350000 | J12: =F12+H12 -> 383728 | K12: =J12-I12 -> -966272
A13: MN Đồng Sơn | B13: Họng tiếp nước ngoài nhà 2 cửa - Ngàm nhôm | C13: 1 | D13: 1 | E13: 2500000 | F13: 975635 | G13: 1000000 | H13: 110390 | I13: =E13+G13 -> 3500000 | J13: =F13+H13 -> 1086025 | K13: =J13-I13 -> -2413975
A14: MN Đồng Sơn | B14: Ống thép tráng kẽm DN65 | C14: 60 | D14: 60 | E14: 13200000 | F14: 7690560 | G14: 7980000 | H14: 5178180 | I14: =E14+G14 -> 21180000 | J14: =F14+H14 -> 12868740 | K14: =J14-I14 -> -8311260
A15: MN Đồng Sơn | B15: Ống thép tráng kẽm DN50 | C15: 40 | D15: 40 | E15: 7200000 | F15: 4016160 | G15: 4040000 | H15: 3172880 | I15: =E15+G15 -> 11240000 | J15: =F15+H15 -> 7189040 | K15: =J15-I15 -> -4050960
A16: MN Đồng Sơn | B16: Co thép đen hàn DN65 | C16: 15 | D16: 15 | E16: 1521000 | F16: 9833415 | G16: 360000 | H16: 1540470 | I16: =E16+G16 -> 1881000 | J16: =F16+H16 -> 11373885 | K16: =J16-I16 -> 9492885 | L16: DT để giá co 650.000đ – lỗi nhập liệu
A17: MN Đồng Sơn | B17: Co thép đen hàn DN50 | C17: 40 | D17: 40 | E17: 2880000 | F17: 2183400 | G17: 640000 | H17: 3529440 | I17: =E17+G17 -> 3520000 | J17: =F17+H17 -> 5712840 | K17: =J17-I17 -> 2192840
A18: MN Đồng Sơn | B18: Tê thép đen hàn DN65 | C18: 10 | D18: 10 | E18: 1620000 | F18: 1705120 | G18: 340000 | H18: 1026980 | I18: =E18+G18 -> 1960000 | J18: =F18+H18 -> 2732100 | K18: =J18-I18 -> 772100
A19: MN Đồng Sơn | B19: Tê thép hàn tráng kẽm DN50 | C19: 10 | D19: 10 | E19: 1380000 | F19: 1527630 | G19: 230000 | H19: 1119290 | I19: =E19+G19 -> 1610000 | J19: =F19+H19 -> 2646920 | K19: =J19-I19 -> 1036920
A20: MN Đồng Sơn | B20: Mặt bích thép đen DN65 + bulong + roăng su | C20: 20 | D20: 20 | E20: 3000000 | F20: 2480420 | G20: 3240000 | H20: 1498540 | I20: =E20+G20 -> 6240000 | J20: =F20+H20 -> 3978960 | K20: =J20-I20 -> -2261040 | L20: Tiên lượng ghi 'bộ' (1 bích); DT tính theo cặp bích, đã quy về 1 bích
A21: MN Đồng Sơn | B21: Ống nhựa DK 25mm | C21: 10 | D21: 100 | E21: 350000 | F21: 1459400 | G21: 140000 | H21: 921000 | I21: =E21+G21 -> 490000 | J21: =F21+H21 -> 2380400 | K21: =J21-I21 -> 1890400 | L21: KL lệch: tiên lượng 10 m, DT 100 m
A22: MN Đồng Sơn | B22: Van bướm lá van inox tay gạt DN65 | C22: 5 | D22: 5 | E22: 2030000 | F22: 5044505 | G22: 530000 | H22: 788500 | I22: =E22+G22 -> 2560000 | J22: =F22+H22 -> 5833005 | K22: =J22-I22 -> 3273005
A23: MN Đồng Sơn | B23: Van 1 chiều cánh cao su DN65 | C23: 2 | D23: 2 | E23: 1596000 | F23: 3320012 | G23: 324000 | H23: 157700 | I23: =E23+G23 -> 1920000 | J23: =F23+H23 -> 3477712 | K23: =J23-I23 -> 1557712
A24: MN Đồng Sơn | B24: Y lọc nối bích DN65. | C24: 2 | D24: 2 | E24: 1488000 | F24: 3200820 | G24: 256000 | H24: 239704 | I24: =E24+G24 -> 1744000 | J24: =F24+H24 -> 3440524 | K24: =J24-I24 -> 1696524
A25: MN Đồng Sơn | B25: Nối mềm nối bích DN65 | C25: 4 | D25: 4 | E25: 1352000 | F25: 7176716 | G25: 512000 | H25: 479408 | I25: =E25+G25 -> 1864000 | J25: =F25+H25 -> 7656124 | K25: =J25-I25 -> 5792124
A26: MN Đồng Sơn | B26: Đồng hồ áp xuất kèm xi phông, van khóa và socket | C26: 2 | D26: 2 | E26: 1700000 | F26: 1200120 | G26: 148000 | H26: 536180 | I26: =E26+G26 -> 1848000 | J26: =F26+H26 -> 1736300 | K26: =J26-I26 -> -111700 | L26: DT trường này 600.000đ, 2 trường kia 163.636đ
A27: MN Đồng Sơn | B27: Van hút DN65 | C27: 2 | D27: 2 | E27: 1358000 | F27: 3680048 | G27: 270000 | H27: 157700 | I27: =E27+G27 -> 1628000 | J27: =F27+H27 -> 3837748 | K27: =J27-I27 -> 2209748
A28: MN Đồng Sơn | B28: Rơ le kiểm tra mực nước | C28: 1 | D28: 1 | E28: 3850000 | F28: 1153955 | G28: 338000 | H28: 31540 | I28: =E28+G28 -> 4188000 | J28: =F28+H28 -> 1185495 | K28: =J28-I28 -> -3002505
A29: MN Đồng Sơn | B29: Van cửa đồng DN25 | C29: 2 | D29: 2 | E29: 500000 | F29: 528332 | G29: 136000 | H29: 63080 | I29: =E29+G29 -> 636000 | J29: =F29+H29 -> 591412 | K29: =J29-I29 -> -44588
A30: MN Đồng Sơn | B30: Tủ điều khiển máy bơm | C30: 1 | D30: 1 | E30: 9850000 | F30: 6500000 | G30: 677000 | H30: 482562 | I30: =E30+G30 -> 10527000 | J30: =F30+H30 -> 6982562 | K30: =J30-I30 -> -3544438
A31: MN Đồng Sơn | B31: Tủ chữa cháy KT: 400x600x200mm, tole dày 0,8mm, sơn tĩnh điện màu đỏ | C31: 6 | D31: 6 | E31: 3246000 | F31: 2016000 | G31: 2844000 | H31: 569562 | I31: =E31+G31 -> 6090000 | J31: =F31+H31 -> 2585562 | K31: =J31-I31 -> -3504438
A32: MN Đồng Sơn | B32: Cuộn vòi chữa cháy Ø50 - L = 20m + lăng phun | C32: 6 | D32: 6 | E32: 4464000 | F32: 3360000 | G32: 528000 | H32: 0 | I32: =E32+G32 -> 4992000 | J32: =F32+H32 -> 3360000 | K32: =J32-I32 -> -1632000 | L32: DT tách vòi + lăng phun, đã cộng lại
A33: MN Đồng Sơn | B33: Van góc FUJI DN50 | C33: 6 | D33: 6 | E33: 2028000 | F33: 1544796 | G33: 972000 | H33: 397404 | I33: =E33+G33 -> 3000000 | J33: =F33+H33 -> 1942200 | K33: =J33-I33 -> -1057800
A34: MN Đồng Sơn | B34: Đèn báo trạm bơm | C34: 1 | D34: 1 | E34: 500000 | F34: 359550 | G34: 81000 | H34: 77888 | I34: =E34+G34 -> 581000 | J34: =F34+H34 -> 437438 | K34: =J34-I34 -> -143562
A35: MN Đồng Sơn | B35: Đèn chiếu sáng sự cố | C35: 1 | D35: 1 | E35: 380000 | F35: 212625 | G35: 100000 | H35: 94915 | I35: =E35+G35 -> 480000 | J35: =F35+H35 -> 307540 | K35: =J35-I35 -> -172460
A36: MN Đồng Sơn | B36: Cáp cáp nguồn trạm bơm 3x10+1x6mm2 | C36: 100 | D36: 100 | E36: 38000000 | F36: 28106400 | G36: 1800000 | H36: 309100 | I36: =E36+G36 -> 39800000 | J36: =F36+H36 -> 28415500 | K36: =J36-I36 -> -11384500
A37: MN Đồng Sơn | B37: Ống nhựa xoắn HDPE 40/30 | C37: 100 | D37: 100 | E37: 2500000 | F37: 1202000 | G37: 1000000 | H37: 2195400 | I37: =E37+G37 -> 3500000 | J37: =F37+H37 -> 3397400 | K37: =J37-I37 -> -102600
A38: MN Đồng Sơn | B38: Lắp đặt máy bơm chữa cháy (2 máy) | C38: 2 | D38: 2 | E38: 0 | F38: 6196 | G38: 9472000 | H38: 1915004 | I38: =E38+G38 -> 9472000 | J38: =F38+H38 -> 1921200 | K38: =J38-I38 -> -7550800 | L38: NC tiên lượng lấy từ 2 dòng máy bơm; giá máy đưa vào dòng Thiết bị
A39: MN Đồng Sơn | B39: Thiết bị (máy bơm, nội quy, kệ, bình, sơ đồ) | C39: 26 | E39: 84090000 | F39: 0 | G39: 750000 | H39: 0 | I39: =E39+G39 -> 84840000 | J39: =F39+H39 -> 0 | K39: =J39-I39 -> -84840000 | L39: DT để ở sheet tb (thiết bị) của file Tổng hợp
A40: MN Đồng Sơn | B40: Vật tư phụ 5% | E40: 12292900 | F40: 0 | G40: 2899500 | H40: 0 | I40: =E40+G40 -> 15192400 | J40: =F40+H40 -> 0 | K40: =J40-I40 -> -15192400 | L40: DT: vật liệu phụ đã nằm trong đơn giá
A41: MN Đồng Sơn | B41: Xây dựng (bể nước, phòng bơm, cầu thang, đào đắp) | E41: 5500000 | F41: 0 | G41: 54436000 | H41: 0 | I41: =E41+G41 -> 59936000 | J41: =F41+H41 -> 0 | K41: =J41-I41 -> -59936000 | L41: DT để ở file Xây lắp riêng
...

Sheet TH-THCS chi tiet
A1: TIỂU HỌC – THCS: CHI TIẾT TỪNG HẠNG MỤC (thành tiền, chi phí trực tiếp, trước thuế)
A3: Trường | B3: Hạng mục | C3: KL 002 | D3: KL DT | E3: VL 002 | F3: VL DT | G3: NC 002 | H3: NC+M DT | I3: Cộng 002 | J3: Cộng DT | K3: Chênh (DT − 002) | L3: Ghi chú
A4: TH số 1 Đồng Sơn | B4: Họng tiếp nước 2 cửa | C4: 1 | D4: 1 | E4: 2500000 | F4: 975635 | G4: 1000000 | H4: 110390 | I4: =E4+G4 -> 3500000 | J4: =F4+H4 -> 1086025 | K4: =J4-I4 -> -2413975
A5: TH số 1 Đồng Sơn | B5: Ống thép tráng kẽm DN65 | C5: 150 | D5: 150 | E5: 33000000 | F5: 19226400 | G5: 19950000 | H5: 12945450 | I5: =E5+G5 -> 52950000 | J5: =F5+H5 -> 32171850 | K5: =J5-I5 -> -20778150
A6: TH số 1 Đồng Sơn | B6: Ống thép tráng kẽm DN50 | C6: 140 | D6: 140 | E6: 25200000 | F6: 14056560 | G6: 14140000 | H6: 11105080 | I6: =E6+G6 -> 39340000 | J6: =F6+H6 -> 25161640 | K6: =J6-I6 -> -14178360
A7: TH số 1 Đồng Sơn | B7: Ống thép tráng kẽm DN80 | C7: 1 | D7: 1 | E7: 278000 | F7: 168795 | G7: 145000 | H7: 93087 | I7: =E7+G7 -> 423000 | J7: =F7+H7 -> 261882 | K7: =J7-I7 -> -161118
A8: TH số 1 Đồng Sơn | B8: Co thép đen hàn DN65 | C8: 10 | D8: 10 | E8: 1014000 | F8: 705020 | G8: 240000 | H8: 1026980 | I8: =E8+G8 -> 1254000 | J8: =F8+H8 -> 1732000 | K8: =J8-I8 -> 478000
A9: TH số 1 Đồng Sơn | B9: Co thép đen hàn DN50 | C9: 35 | D9: 35 | E9: 2520000 | F9: 1910475 | G9: 560000 | H9: 3088260 | I9: =E9+G9 -> 3080000 | J9: =F9+H9 -> 4998735 | K9: =J9-I9 -> 1918735
A10: TH số 1 Đồng Sơn | B10: Tê giảm DN100/65 | C10: 1 | D10: 1 | E10: 235000 | F10: 190704 | G10: 45000 | H10: 163548 | I10: =E10+G10 -> 280000 | J10: =F10+H10 -> 354252 | K10: =J10-I10 -> 74252
A11: TH số 1 Đồng Sơn | B11: Tê DN65 + tê giảm DN65/50 | C11: 10 | D11: 10 | E11: 1725000 | F11: 1630115 | G11: 380000 | H11: 1026980 | I11: =E11+G11 -> 2105000 | J11: =F11+H11 -> 2657095 | K11: =J11-I11 -> 552095
A12: TH số 1 Đồng Sơn | B12: Tê thép hàn tráng kẽm DN50 | C12: 10 | D12: 10 | E12: 1380000 | F12: 1527630 | G12: 230000 | H12: 1119290 | I12: =E12+G12 -> 1610000 | J12: =F12+H12 -> 2646920 | K12: =J12-I12 -> 1036920
A13: TH số 1 Đồng Sơn | B13: Côn giảm DN80/65 | C13: 1 | D13: 1 | E13: 85000 | F13: 88862 | G13: 85000 | H13: 141931 | I13: =E13+G13 -> 170000 | J13: =F13+H13 -> 230793 | K13: =J13-I13 -> 60793
A14: TH số 1 Đồng Sơn | B14: Mặt bích DN80 | C14: 1 | D14: 1 | E14: 110000 | F14: 349544 | G14: 55000 | H14: 74927 | I14: =E14+G14 -> 165000 | J14: =F14+H14 -> 424471 | K14: =J14-I14 -> 259471
A15: TH số 1 Đồng Sơn | B15: Roăng su DN80 | C15: 1 | D15: 1 | E15: 23000 | F15: 150000 | G15: 15000 | H15: 0 | I15: =E15+G15 -> 38000 | J15: =F15+H15 -> 150000 | K15: =J15-I15 -> 112000
... A20: TH số 1 Đồng Sơn | B20: Van góc DN50 | C20: 14 | D20: 14 | E20: 4732000 | F20: 3604524 | G20: 2268000 | H20: 927276 | I20: =E20+G20 -> 7000000 | J20: =F20+H20 -> 4531800 | K20: =J20-I20 -> -2468200
A21: TH số 1 Đồng Sơn | B21: Thiết bị (nội quy, kệ, bình, sơ đồ) | C21: 10 | E21: 4500000 | F21: 0 | G21: 810000 | H21: 0 | I21: =E21+G21 -> 5310000 | J21: =F21+H21 -> 0 | K21: =J21-I21 -> -5310000 | L21: DT để ở sheet tb (thiết bị)
A22: TH số 1 Đồng Sơn | B22: Vật tư phụ 5% | E22: 5001850 | F22: 0 | G22: 2415550 | H22: 0 | I22: =E22+G22 -> 7417400 | J22: =F22+H22 -> 0 | K22: =J22-I22 -> -7417400 | L22: DT: vật liệu phụ đã nằm trong đơn giá
A23: TH số 1 Đồng Sơn | B23: Xây dựng (cầu thang, đào, đắp) | C23: 157.33333 | E23: 0 | F23: 0 | G23: 5192000 | H23: 0 | I23: =E23+G23 -> 5192000 | J23: =F23+H23 -> 0 | K23: =J23-I23 -> -5192000 | L23: DT để ở file Xây lắp riêng
A24: TH số 2 Đồng Sơn | B24: Ống luồn dây / ống nhựa D20 | C24: 300 | D24: 300 | E24: 4500000 | F24: 2683500 | G24: 8100000 | H24: 14239200 | I24: =E24+G24 -> 12600000 | J24: =F24+H24 -> 16922700 | K24: =J24-I24 -> 4322700
A25: TH số 2 Đồng Sơn | B25: Họng tiếp nước 2 cửa | C25: 1 | D25: 1 | E25: 2500000 | F25: 975635 | G25: 1000000 | H25: 110390 | I25: =E25+G25 -> 3500000 | J25: =F25+H25 -> 1086025 | K25: =J25-I25 -> -2413975
A26: TH số 2 Đồng Sơn | B26: Ống thép tráng kẽm DN65 | C26: 140 | D26: 140 | E26: 30800000 | F26: 17944640 | G26: 18620000 | H26: 12082420 | I26: =E26+G26 -> 49420000 | J26: =F26+H26 -> 30027060 | K26: =J26-I26 -> -19392940
A27: TH số 2 Đồng Sơn | B27: Ống thép tráng kẽm DN50 | C27: 90 | D27: 90 | E27: 16200000 | F27: 9036360 | G27: 9090000 | H27: 7138980 | I27: =E27+G27 -> 25290000 | J27: =F27+H27 -> 16175340 | K27: =J27-I27 -> -9114660
A28: TH số 2 Đồng Sơn | B28: Co thép đen hàn DN65 | C28: 10 | D28: 10 | E28: 1014000 | F28: 705020 | G28: 240000 | H28: 1026980 | I28: =E28+G28 -> 1254000 | J28: =F28+H28 -> 1732000 | K28: =J28-I28 -> 478000
A29: TH số 2 Đồng Sơn | B29: Co thép đen hàn DN50 | C29: 50 | D29: 50 | E29: 3600000 | F29: 2729250 | G29: 800000 | H29: 4411800 | I29: =E29+G29 -> 4400000 | J29: =F29+H29 -> 7141050 | K29: =J29-I29 -> 2741050
A30: TH số 2 Đồng Sơn | B30: Tê DN65 + tê giảm DN65/50 | C30: 6 | D30: 6 | E30: 1098000 | F30: 1023072 | G30: 252000 | H30: 616188 | I30: =E30+G30 -> 1350000 | J30: =F30+H30 -> 1639260 | K30: =J30-I30 -> 289260
A31: TH số 2 Đồng Sơn | B31: Tê thép hàn tráng kẽm DN50 | C31: 10 | D31: 10 | E31: 1380000 | F31: 1527630 | G31: 230000 | H31: 1119290 | I31: =E31+G31 -> 1610000 | J31: =F31+H31 -> 2646920 | K31: =J31-I31 -> 1036920
A32: TH số 2 Đồng Sơn | B32: Rơ le kiểm tra mực nước | C32: 1 | D32: 1 | E32: 3850000 | F32: 1153955 | G32: 338000 | H32: 31540 | I32: =E32+G32 -> 4188000 | J32: =F32+H32 -> 1185495 | K32: =J32-I32 -> -3002505
A33: TH số 2 Đồng Sơn | B33: Van cửa đồng DN25 | D33: 2 | E33: 0 | F33: 528332 | G33: 0 | H33: 63080 | I33: =E33+G33 -> 0 | J33: =F33+H33 -> 591412 | K33: =J33-I33 -> 591412 | L33: KL lệch / chỉ có ở một bên
A34: TH số 2 Đồng Sơn | B34: Tủ chữa cháy | C34: 12 | D34: 12 | E34: 6492000 | F34: 4032000 | G34: 5688000 | H34: 1139124 | I34: =E34+G34 -> 12180000 | J34: =F34+H34 -> 5171124 | K34: =J34-I34 -> -7008876
A35: TH số 2 Đồng Sơn | B35: Cuộn vòi D50 + lăng phun | C35: 12 | D35: 12 | E35: 8928000 | F35: 6720000 | G35: 1056000 | H35: 0 | I35: =E35+G35 -> 9984000 | J35: =F35+H35 -> 6720000 | K35: =J35-I35 -> -3264000
A36: TH số 2 Đồng Sơn | B36: Van góc DN50 | C36: 12 | D36: 12 | E36: 4056000 | F36: 3089592 | G36: 1944000 | H36: 794808 | I36: =E36+G36 -> 6000000 | J36: =F36+H36 -> 3884400 | K36: =J36-I36 -> -2115600
A37: TH số 2 Đồng Sơn | B37: Dây nguồn đèn 2x0,75 | C37: 300 | D37: 300 | E37: 3900000 | F37: 4206900 | G37: 3000000 | H37: 2176200 | I37: =E37+G37 -> 6900000 | J37: =F37+H37 -> 6383100 | K37: =J37-I37 -> -516900
A38: TH số 2 Đồng Sơn | B38: Đèn exit | C38: 2 | D38: 2 | E38: 700000 | F38: 425250 | G38: 200000 | H38: 189830 | I38: =E38+G38 -> 900000 | J38: =F38+H38 -> 615080 | K38: =J38-I38 -> -284920
A39: TH số 2 Đồng Sơn | B39: Đèn chiếu sáng sự cố | C39: 16 | D39: 16 | E39: 6080000 | F39: 3402000 | G39: 1600000 | H39: 1518640 | I39: =E39+G39 -> 7680000 | J39: =F39+H39 -> 4920640 | K39: =J39-I39 -> -2759360
A40: TH số 2 Đồng Sơn | B40: Thiết bị (nội quy, kệ, bình, sơ đồ) | C40: 8 | E40: 3600000 | F40: 0 | G40: 648000 | H40: 0 | I40: =E40+G40 -> 4248000 | J40: =F40+H40 -> 0 | K40: =J40-I40 -> -4248000 | L40: DT để ở sheet tb (thiết bị)
A41: TH số 2 Đồng Sơn | B41: Vật tư phụ 5% | E41: 4175900 | F41: 0 | G41: 1995300 | H41: 0 | I41: =E41+G41 -> 6171200 | J41: =F41+H41 -> 0 | K41: =J41-I41 -> -6171200 | L41: DT: vật liệu phụ đã nằm trong đơn giá
A42: TH số 2 Đồng Sơn | B42: Xây dựng (cầu thang, đào, đắp) | C42: 140 | E42: 6000000 | F42: 0 | G42: 46488000 | H42: 0 | I42: =E42+G42 -> 52488000 | J42: =F42+H42 -> 0 | K42: =J42-I42 -> -52488000 | L42: DT để ở file Xây lắp riêng
A43: THCS số 1 Đồng Sơn | B43: Tiếp địa | C43: 1 | D43: 1 | E43: 850000 | F43: 282800 | G43: 500000 | H43: 100928 | I43: =E43+G43 -> 1350000 | J43: =F43+H43 -> 383728 | K43: =J43-I43 -> -966272
A44: THCS số 1 Đồng Sơn | B44: Trung tâm báo cháy | C44: 1 | D44: 1 | E44: 12177000 | F44: 8931825 | G44: 2030000 | H44: 832812 | I44: =E44+G44 -> 14207000 | J44: =F44+H44 -> 9764637 | K44: =J44-I44 -> -4442363
A45: THCS số 1 Đồng Sơn | B45: Còi đèn báo cháy kết hợp | C45: 10 | D45: 10 | E45: 7440000 | F45: 2575500 | G45: 810000 | H45: 778882 | I45: =E45+G45 -> 8250000 | J45: =F45+H45 -> 3354382 | K45: =J45-I45 -> -4895618
...

Sheet Can xem lai
A1: CÁC ĐIỂM CẦN XEM LẠI TRƯỚC KHI CHỐT
A3: # | B3: Ở đâu | C3: Nội dung | D3: Ảnh hưởng / đề xuất
A4: 1 | B4: Dự toán – Tổng hợp mầm non, sheet tb | C4: Máy bơm điện 13 tr, bơm diesel 20,1 tr; giá vốn 15,4 / 27,72 tr | D4: Dưới giá vốn ≈ 30 tr cho 6 máy (thiết bị không có chi phí chung bù). Nâng tối thiểu bằng báo giá
A5: 2 | B5: Dự toán – thiết bị TH-THCS và bình/kệ/nội quy | C5: Sơ đồ 150.000, bình 550.000, kệ 110.000, nội quy 40.000; giá vốn 442.000 / 652.000 / 137.000 / 53.000 | D5: Dưới giá vốn ≈ 16 tr
A6: 3 | B6: Dự toán mầm non – Giá tháng | C6: Co thép đen DN65 = 650.000đ (TH-THCS 65.000đ, giá vốn 53.000đ) | D6: Lỗi nhập liệu, đội ≈ 23 tr VL. Thẩm tra sẽ cắt
A7: 4 | B7: Dự toán – 2 file PCCC | C7: Đầu báo khói: mầm non 427.273đ, TH-THCS 250.000đ (giá vốn 242.000đ) | D7: Không thống nhất; nếu thẩm tra đưa mầm non về 250.000 thì giảm ≈ 29 tr VL
A8: 5 | B8: Dự toán mầm non – Đồng Sơn | C8: Đồng hồ áp suất 600.000đ, 2 trường kia 163.636đ (giá vốn 300.000đ) | D8: Đưa 2 trường kia lên ≥ 300.000
A9: 6 | B9: Tiên lượng 001 – Đồng Sơn / Thuận Đức | C9: KL ống nhựa D25 Đồng Sơn 10 m (DT 100 m); tê DN65 Thuận Đức 10 (DT 15) | D9: Đối chiếu lại bản vẽ
