Workbook

Sheet TH
A1: BẢNG TỔNG DỰ TOÁN
A2: CÔNG TRÌNH: HỆ THỐNG PHÒNG CHÁY CHỮA CHÁY CÁC TRƯỜNG MẦM NON TRÊN ĐỊA BÀN PHƯỜNG ĐỒNG SƠN
B3: Khoản mục chi phí | C3: Ký hiệu | D3: Cách tính | E3: Giá trị trước thuế | F3: Thuế VAT (8%) | G3: Giá trị sau thuế
A4: I | B4: Chi phí xây lắp | C4: GXD | D4: G1+G2 | E4: =E5+E12 -> 1.6121334e+09 | F4: =E4*8% -> 1.2897067e+08 | G4: =ROUND(E4+F4,-3) -> 1741104000
A5: 1.1 | B5: Chi phí xây dựng của công trình | C5: Gxdct | D5: Gxdct1+...+Gxdct4 | E5: =SUM(E6:E11) -> 1594592865 | F5: =E5*8% -> 1.2756743e+08 | G5: =ROUND(E5+F5,-3) -> 1722160000
A6: 1.1.1 | B6: PCCC | C6: Gxdct1 | D6: Có dự toán chi tiết | E6: 1215750394 | F6: =E6*8% -> 97260032 | G6: =ROUND(E6+F6,-3) -> 1313010000
A7: 1.1.2 | B7: Xây lắp Trường tiểu học Nghĩa Ninh | C7: Gxdct2 | D7: Có dự toán chi tiết | E7: 101163519 | F7: =E7*8% -> 8093081.5 | G7: =ROUND(E7+F7,-3) -> 109257000
A8: 1.1.3 | B8: Xây lắp Trường tiểu học số 1 Đồng Sơn | C8: Gxdct3 | D8: Có dự toán chi tiết | E8: 39743608 | F8: =E8*8% -> 3179488.6 | G8: =ROUND(E8+F8,-3) -> 42923000
A9: 1.1.4 | B9: Xây lắp Trường tiểu học số 2 Đồng Sơn | C9: Gxdct4 | D9: Có dự toán chi tiết | E9: 80058943 | F9: =E9*8% -> 6404715.4 | G9: =ROUND(E9+F9,-3) -> 86464000
A10: 1.1.5 | B10: Xây lắp Trường THCS số 1 Đồng Sơn | C10: Gxdct5 | D10: Có dự toán chi tiết | E10: 117867626 | F10: =E10*8% -> 9429410.1 | G10: =ROUND(E10+F10,-3) -> 127297000
A11: 1.1.6 | B11: Xây lắp Trường THCS Bắc Nghĩa | C11: Gxdct6 | D11: =D10 -> Có dự toán chi tiết | E11: 40008775 | F11: =E11*8% -> 3200702 | G11: =ROUND(E11+F11,-3) -> 43209000
A12: 1.2 | B12: Chi phí nhà tạm để ở và điều hành thi công | C12: Glt | D12: 1,1%*Gxdct | E12: =E5*1.1% -> 17540522 | F12: =E12*8% -> 1403241.7 | G12: =ROUND(E12+F12,-3) -> 18944000
A13: II | B13: Chi phí thiết bị | C13: Gtb | D13: =D16 -> Có dự toán chi tiết | E13: =G13/1.08 -> 17550000 | F13: =E13*8% -> 1404000 | G13: =tb!L4 -> 18954000
A14: II | B14: Chi phí QLDA | C14: QL | D14: (G+TB)*3,446% | E14: =(E4+E13)*3.446% -> 56158889 | G14: =ROUND((F14+E14),-3) -> 56159000
A15: IV | B15: Chi phí tư vấn đầu tư xây dựng: | C15: GTV | D15: TV1+TV2+...+TV5 | E15: =ROUND(SUM(E16:E25),-3) -> 126902000 | F15: =ROUND(SUM(F16:F25),-3) -> 10152000 | G15: =ROUND(SUM(G16:G25),-3) -> 137053000
A16: 5.1 | B16: Chi phí đo vẽ hiện trạng | C16: TV1 | D16: Có dự toán chi tiết | E16: =G16/1.08 -> 13888889 | F16: =E16*8% -> 1111111.1 | G16: 15000000
A17: 5.2 | B17: Chi phí lập báo cáo kinh tế kỹ thuật (VB 9947/BXD-VPB ngày 29/6/2026) | C17: TV2 | D17: 5,933%*Gxdct | E17: =(E5+E13)*M21% -> 95653030 | F17: =E17*8% -> 7652242.4 | G17: =ROUND(E17+F17,-3) -> 103305000
A18: 5.3 | B18: Chi phí thẩm tra thiết kế bản vẽ thi công (VB 9947/BXD-VPB ngày 29/6/2026) | C18: TV3 | D18: 0,258%*Gxdct | E18: =E5*0.258% -> 4114049.6 | F18: =E18*8% -> 329123.97 | G18: =ROUND(E18+F18,-3) -> 4443000 | L18: 1 | M18: 6.5
A19: 5.4 | B19: Chi phí thẩm tra dự toán (VB 9947/BXD-VPB ngày 29/6/2026) | C19: TV4 | D19: 0,25%*Gxdct | E19: =E5*0.25% -> 3986482.2 | F19: =E19*8% -> 318918.57 | G19: =ROUND(E19+F19,-3) -> 4305000 | L19: 3 | M19: 4.7
A20: 5.5 | B20: Chi phí thẩm định giá | C20: TV5 | D20: Tạm tính | E20: =G20/1.08 -> 9259259.3 | F20: =E20*8% -> 740740.74 | G20: 10000000
A21: 5.6 | B21: Chi phí lập hồ sơ mời thầu (VB 9947/BXD-VPB ngày 29/6/2026) | C21: TV6 | D21: (GXD+Gtb)*0,432%*45% | F21: =E21*8% -> 0 | G21: =ROUND(E21+F21,-3) -> 0 | L21: =(E4+E13)/10^9 -> 1.6296834 | M21: =(L19-L21)*(M18-M19)/(L19-L18)+M19 -> 5.933285
A22: 5.7 | B22: Chi phí đánh giá hồ sơ dự thầu (VB 9947/BXD-VPB ngày 29/6/2026) | C22: TV7 | D22: (GXD+Gtb)*0,432%*55% | F22: =E22*8% -> 0 | G22: =ROUND(E22+F22,-3) -> 0
A23: 5.8 | B23: Chi phí giám sát thi công (VB 9947/BXD-VPB ngày 29/6/2026) | C23: TV8 | D23: 3,285%*Gxdct+0,844%*Gtb | F23: =E23*8% -> 0 | G23: =ROUND(E23+F23,-3) -> 0
A24: 5.8 | B24: Phí thẩm định hồ sơ mời thầu (NĐ 214/2025/NĐ-CP ngày 04/8/2025) | C24: TV9 | D24: 0.1%*(Gxd+Gtb) (tối thiểu 2.000.000đ) | F24: =E24*8% -> 0 | G24: =ROUND(E24+F24,-3) -> 0 | H24: Bỏ chi phí này theo điểm b khoản 1 điều 81 Nghị định 214/2025
A25: 5.9 | B25: Phí thẩm định kết quả lựa chọn nhà thầu (NĐ 214/2025/NĐ-CP ngày 04/8/2025) | C25: TV9 | D25: 0.1%*(GXD+Gtb) (tối thiểu 3.000.000đ) | F25: =E25*8% -> 0 | G25: =ROUND(E25+F25,-3) -> 0 | K25: 6.5
A26: V | B26: Chi phí khác | C26: GK | D26: CK1+CK2 | E26: =ROUND(SUM(E27:E29),-3) -> 12265000 | F26: =ROUND(SUM(F27:F29),-3) -> 0 | G26: =ROUND(SUM(G27:G29),-3) -> 12265000 | K26: 5 | L26: 0.57 | M26: =+L26-((L26-L27)*(K25-K26)/(K27-K26)) -> 0.516
A27: 6.1 | B27: Chi phí bảo hiểm công trình | C27: CK1 | D27: 0.08%*G | F27: =E27*0.08 -> 0 | G27: =ROUND(E27+F27,-3) -> 0 | H27: Kiểm tra lại công trình hạ tầng kỹ thuật có chi phí bảo hiểm không | K27: 10 | L27: 0.39
A28: 6.1 | B28: Chi phí thẩm tra phê duyệt quyết toán (Nghị định 193/2026/NĐ-CP ngày 01/6/2026) | C28: CK1 | D28: 0,57%*TM | E28: =0.57%*2064000000 -> 11764800 | G28: =ROUND(E28+F28,-3) -> 11765000 | H28: Nội suy theo điểm c khoản 1 Điều 20 nghị định 139/2026
A29: 6.2 | B29: Phí thẩm định báo cáo kinh tế kỹ thuật | C29: CK2 | D29: 0,019%*TMĐT(tối thiểu 500.000đ) | E29: 500000 | G29: =ROUND(E29+F29,-3) -> 500000 | I29: =0.019%*6000000000 -> 1140000
A30: VI | B30: Chi phí dự phòng | C30: GDP | D30: 5%*(GXD+Gtb+QL+GTV+GK) | G30: =ROUND(5%*(G4+G14+G15+G26+G13),-3) -> 98277000 | I30: =G30/(G4+G14+G15+G26) -> 0.050486982 | K30: =2%*(G4+G14+G15+G26) -> 38931620 | L30: =K30-G30 -> -59345380
B31: Giá trị dự toán | C31: VTM | D31: I-VI | G31: =ROUND(G4+G14+G15+G30+G26+G13,-3) -> 2063812000
B32: Làm tròn | G32: =ROUND((G31),-6) -> 2064000000
E34: Quảng Bình, ngày tháng năm 2026
F35: Người lập +Chủ trì

Sheet tb
A1: BẢNG TỔNG HỢP THIẾT BỊ
A2: =TH!A2 -> CÔNG TRÌNH: HỆ THỐNG PHÒNG CHÁY CHỮA CHÁY CÁC TRƯỜNG MẦM NON TRÊN ĐỊA BÀN PHƯỜNG ĐỒNG SƠN
A3: STT | B3: Tên thiết bị | C3: Đơn vị | D3: Trường THCS Bắc Nghĩa | E3: Trường THCS số 1 Đồng Sơn | F3: Trường tiểu học Nghĩa Ninh | G3: Trường tiểu học số 1 Đồng Sơn | H3: Trường tiểu học số 2 Đồng Sơn | I3: Tổng số lượng | J3: Đơn giá trước thế | K3: Đơn giá sau thế | L3: Thành tiền
A4: I | B4: Thiết bị | L4: =SUM(L5:L8) -> 18954000
A5: 1 | B5: Bộ nội quy tiêu lệnh chữa cháy - Chất liệu bằng tôn | C5: cái | F5: 5 | I5: =SUM(D5:H5) -> 5 | J5: 40000 | K5: =J5*1.08 -> 43200 | L5: =K5*I5 -> 216000
A6: 2 | B6: Kệ đỡ bình chữa cháy | C6: cái | E6: 5 | F6: 5 | I6: =SUM(D6:H6) -> 10 | J6: 110000 | K6: =J6*1.08 -> 118800 | L6: =K6*I6 -> 1188000
A7: 3 | B7: BÌNH BỘT ABC 8KG | C7: cái | E7: 10 | F7: 10 | I7: =SUM(D7:H7) -> 20 | J7: 550000 | K7: =J7*1.08 -> 594000 | L7: =K7*I7 -> 11880000
A8: 4 | B8: Sơ đồ chỉ dẫn thoát hiểm 400x600 | C8: cái | D8: 5 | E8: 6 | F8: 6 | G8: 10 | H8: 8 | I8: =SUM(D8:H8) -> 35 | J8: 150000 | K8: =J8*1.08 -> 162000 | L8: =K8*I8 -> 5670000

Sheet Bao gia
A1: BẢNG TỔNG HỢP THIẾT BỊ
A2: =TH!A2 -> CÔNG TRÌNH: HỆ THỐNG PHÒNG CHÁY CHỮA CHÁY CÁC TRƯỜNG MẦM NON TRÊN ĐỊA BÀN PHƯỜNG ĐỒNG SƠN
A3: STT | B3: Tên thiết bị | C3: Đơn vị | D3: Khối lượng | E3: Đơn giá trước thế | F3: Đơn giá sau thế | G3: Thành tiền sau thế
A4: 1 | B4: Trung tâm báo cháy 10 kênh bao gồm Acquy | C4: cái | D4: 2 | E4: 7790909 | F4: =E4*1.08 -> 8414181.7 | G4: =F4*D4 -> 16828363
A5: =A4+1 -> 2 | B5: Trung tâm báo cháy 8 kênh bao gồm Acquy | C5: cái | E5: 7454545 | F5: =E5*1.08 -> 8050908.6 | G5: =F5*D5 -> 0
A6: =A5+1 -> 3 | B6: Trung tâm báo cháy 5 kênh bao gồm Acquy | C6: cái | E6: 7127273 | F6: =E6*1.08 -> 7697454.8 | G6: =F6*D6 -> 0
A7: =A6+1 -> 4 | B7: Còi đèn báo cháy kết hợp | C7: cái | D7: 21 | E7: 1800000 | F7: =E7*1.08 -> 1944000 | G7: =F7*D7 -> 40824000
A8: =A7+1 -> 5 | B8: Nút ấn khẩn tròn lắp nổi | C8: cái | D8: 21 | E8: 281818 | F8: =E8*1.08 -> 304363.44 | G8: =F8*D8 -> 6391632.2
A9: =A8+1 -> 6 | B9: Đầu báo khói quang 24VDC | C9: cái | D9: 287 | E9: 427273 | F9: =E9*1.08 -> 461454.84 | G9: =F9*D9 -> 1.3243754e+08
A10: =A9+1 -> 7 | B10: Đèn báo phòng | C10: cái | D10: 70 | E10: 181818 | F10: =E10*1.08 -> 196363.44 | G10: =F10*D10 -> 13745441
A11: =A10+1 -> 8 | B11: Đầu báo nhiệt cố định 70 độ C | C11: cái | E11: 272727 | F11: =E11*1.08 -> 294545.16 | G11: =F11*D11 -> 0
A12: =A11+1 -> 9 | B12: Cọc tiếp địa mạ đồng D16 L=2,4m | C12: cái | D12: 2 | E12: 225000 | F12: =E12*1.08 -> 243000 | G12: =F12*D12 -> 486000
A13: =A12+1 -> 10 | B13: Co thép đen hàn DN65 | C13: cái | D13: 56 | E13: 30000 | F13: =E13*1.08 -> 32400 | G13: =F13*D13 -> 1814400
A14: =A13+1 -> 11 | B14: Co thép đen hàn DN50 | C14: cái | D14: 265 | E14: 21000 | F14: =E14*1.08 -> 22680 | G14: =F14*D14 -> 6010200
A15: =A14+1 -> 12 | B15: Tê thép đen hàn DN65 | C15: cái | D15: 22 | E15: 97500 | F15: =E15*1.08 -> 105300 | G15: =F15*D15 -> 2316600
A16: =A15+1 -> 13 | B16: Tê giảm thép đen hàn DN65 | C16: cái | D16: 10 | E16: 97500 | F16: =E16*1.08 -> 105300 | G16: =F16*D16 -> 1053000
A17: =A16+1 -> 14 | B17: Tê thép hàn tráng kẽm DN50 | C17: cái | D17: 52 | E17: 55692 | F17: =E17*1.08 -> 60147.36 | G17: =F17*D17 -> 3127662.7
A18: =A17+1 -> 15 | B18: Tê giảm thép hàn DN100/65 | C18: cái | D18: 1 | E18: 195000 | F18: =E18*1.08 -> 210600 | G18: =F18*D18 -> 210600
A19: =A18+1 -> 16 | B19: Tê giảm thép hàn DN65/50 | C19: cái | D19: 5 | E19: 120000 | F19: =E19*1.08 -> 129600 | G19: =F19*D19 -> 648000
A20: =A19+1 -> 17 | B20: Côn giảm thép hàn DN80/65 | C20: cái | D20: 1 | E20: 75000 | F20: =E20*1.08 -> 81000 | G20: =F20*D20 -> 81000
A21: =A20+1 -> 18 | B21: Mặt bích thép DN80 | C21: cái | D21: 1 | E21: 321000 | F21: =E21*1.08 -> 346680 | G21: =F21*D21 -> 346680
A22: =A21+1 -> 19 | B22: Roăng su DN80 | C22: cái | D22: 1 | E22: 23000 | F22: =E22*1.08 -> 24840 | G22: =F22*D22 -> 24840
A23: =A22+1 -> 20 | B23: ='[1]ĐƠN GIÁ'!B53 -> Van 1 chiều DN80 | C23: cái | D23: 1 | E23: 895000 | F23: =E23*1.08 -> 966600 | G23: =F23*D23 -> 966600
A24: =A23+1 -> 21 | B24: Mặt bích thép đen DN65 + bulong + roăng su | C24: cái | E24: 248000 | F24: =E24*1.08 -> 267840 | G24: =F24*D24 -> 0
A25: =A24+1 -> 22 | B25: Đồng hồ áp xuất kèm xi phông, van khóa và socket | C25: cái | E25: 163636 | F25: =E25*1.08 -> 176726.88 | G25: =F25*D25 -> 0
A26: =A25+1 -> 23 | B26: Rơ le kiểm tra mực nước | C26: cái | D26: 4 | E26: 1150000 | F26: =E26*1.08 -> 1242000 | G26: =F26*D26 -> 4968000
A27: =A26+1 -> 24 | B27: Tủ điều khiển máy bơm | C27: cái | E27: 9772727 | F27: =E27*1.08 -> 10554545 | G27: =F27*D27 -> 0
A28: =A27+1 -> 25 | B28: Máy bơm chữa cháy động cơ điện Q: 45m3/h - H: 40m.c.n | C28: cái | E28: 30000000 | F28: =E28*1.08 -> 32400000 | G28: =F28*D28 -> 0
A29: =A28+1 -> 26 | B29: Máy bơm chữa cháy động cơ nhiên liệu Q: 45m3/h - H: 40m.c.n | C29: cái | E29: 50000000 | F29: =E29*1.08 -> 54000000 | G29: =F29*D29 -> 0
A30: =A29+1 -> 27 | B30: Tủ chữa cháy KT: 400x600x200mm, tole dày 0,8mm, sơn tĩnh điện màu đỏ | C30: cái | D30: 57 | E30: 336364 | F30: =E30*1.08 -> 363273.12 | G30: =F30*D30 -> 20706568
A31: =A30+1 -> 28 | B31: Cuộn vòi chữa cháy Ø50 - L = 20m + lăng phun | C31: cái | D31: 70 | E31: 600000 | F31: =E31*1.08 -> 648000 | G31: =F31*D31 -> 45360000
A32: =A31+1 -> 29 | B32: Lăng phun DN50 | C32: cái | D32: 70 | E32: 104545 | F32: =E32*1.08 -> 112908.6 | G32: =F32*D32 -> 7903602
A33: =A32+1 -> 30 | B33: Van góc FUJI DN50 | C33: cái | D33: 70 | E33: 385000 | F33: =E33*1.08 -> 415800 | G33: =F33*D33 -> 29106000
A34: =A33+1 -> 31 | B34: Bộ nội quy tiêu lệnh chữa cháy - Chất liệu bằng tôn | C34: cái | D34: =tb!I5 -> 5 | E34: 120000 | F34: =E34*1.08 -> 129600 | G34: =F34*D34 -> 648000
A35: =A34+1 -> 32 | B35: Kệ đỡ bình chữa cháy | C35: cái | D35: =tb!I6 -> 10 | E35: 150000 | F35: =E35*1.08 -> 162000 | G35: =F35*D35 -> 1620000
A36: =A35+1 -> 33 | B36: BÌNH BỘT ABC 8KG | C36: cái | D36: =tb!I7 -> 20 | E36: 650000 | F36: =E36*1.08 -> 702000 | G36: =F36*D36 -> 14040000
A37: =A36+1 -> 34 | B37: Đèn exit | C37: cái | D37: 11 | E37: 380000 | F37: =E37*1.08 -> 410400 | G37: =F37*D37 -> 4514400
A38: =A37+1 -> 35 | B38: Đèn chiếu sáng sự cố | C38: cái | D38: 54 | E38: 380000 | F38: =E38*1.08 -> 410400 | G38: =F38*D38 -> 22161600
A39: =A38+1 -> 36 | B39: Đèn báo trạm bơm | C39: cái | E39: 200000 | F39: =E39*1.08 -> 216000 | G39: =F39*D39 -> 0
A40: =A39+1 -> 37 | B40: Sơ đồ chỉ dẫn thoát hiểm 400x600 | C40: cái | D40: =tb!I8 -> 35 | E40: 300000 | F40: =E40*1.08 -> 324000 | G40: =F40*D40 -> 11340000
...
